Workbook

Sheet SP_INVOICE_REPORT
A1: fulfilmentDate | B1: spBookingRefNumber | C1: bookingId | D1: customerName | E1: totalPax | F1: persons | G1: netPrice | H1: status | I1: beId | J1: paymentMethod | K1: reason | M1: count
A2: 25569 | C2: 27063716 | E2: 0 | F2: { } | G2: 102.38 | H2: SP_INVOICE_ENTRY_STATUS_ALREADY_AUTO_RECONCILED | I2: 507 | K2: Reconciliation ALREADY auto reconciled | M2: =COUNTIF(RECONCILIATION_REPORT!B:B,SP_INVOICE_REPORT!C2) -> 17
A3: 25569 | C3: 27070292 | E3: 0 | F3: { } | G3: 68.25 | H3: SP_INVOICE_ENTRY_STATUS_ALREADY_AUTO_RECONCILED | I3: 507 | K3: Reconciliation ALREADY auto reconciled | M3: =COUNTIF(RECONCILIATION_REPORT!B:B,SP_INVOICE_REPORT!C3) -> 5
A4: 25569 | C4: 27070478 | E4: 0 | F4: { } | G4: 97.5 | H4: SP_INVOICE_ENTRY_STATUS_DISCREPANCY | I4: 507 | K4: Net price discrepancy | M4: =COUNTIF(RECONCILIATION_REPORT!B:B,SP_INVOICE_REPORT!C4) -> 9
A5: 25569 | C5: 27075844 | E5: 0 | F5: { } | G5: 68.25 | H5: SP_INVOICE_ENTRY_STATUS_ALREADY_AUTO_RECONCILED | I5: 507 | K5: Reconciliation ALREADY auto reconciled | M5: =COUNTIF(RECONCILIATION_REPORT!B:B,SP_INVOICE_REPORT!C5) -> 4
A6: 25569 | C6: 27079427 | E6: 0 | F6: { } | G6: 68.25 | H6: SP_INVOICE_ENTRY_STATUS_ALREADY_AUTO_RECONCILED | I6: 507 | K6: Reconciliation ALREADY auto reconciled | M6: =COUNTIF(RECONCILIATION_REPORT!B:B,SP_INVOICE_REPORT!C6) -> 2
A7: 25569 | C7: 27081400 | E7: 0 | F7: { } | G7: 68.25 | H7: SP_INVOICE_ENTRY_STATUS_ALREADY_AUTO_RECONCILED | I7: 507 | K7: Reconciliation ALREADY auto reconciled | M7: =COUNTIF(RECONCILIATION_REPORT!B:B,SP_INVOICE_REPORT!C7) -> 2
A8: 25569 | C8: 27082263 | E8: 0 | F8: { } | G8: 68.25 | H8: SP_INVOICE_ENTRY_STATUS_DISCREPANCY | I8: 507 | K8: Net price discrepancy | M8: =COUNTIF(RECONCILIATION_REPORT!B:B,SP_INVOICE_REPORT!C8) -> 1
A9: 25569 | C9: 27082886 | E9: 0 | F9: { } | G9: 68.25 | H9: SP_INVOICE_ENTRY_STATUS_DISCREPANCY | I9: 507 | K9: Net price discrepancy | M9: =COUNTIF(RECONCILIATION_REPORT!B:B,SP_INVOICE_REPORT!C9) -> 1
A10: 25569 | C10: 27084375 | E10: 0 | F10: { } | G10: 68.25 | H10: SP_INVOICE_ENTRY_STATUS_ALREADY_AUTO_RECONCILED | I10: 507 | K10: Reconciliation ALREADY auto reconciled | M10: =COUNTIF(RECONCILIATION_REPORT!B:B,SP_INVOICE_REPORT!C10) -> 2
A11: 25569 | C11: 27085550 | E11: 0 | F11: { } | G11: 68.25 | H11: SP_INVOICE_ENTRY_STATUS_ALREADY_AUTO_RECONCILED | I11: 507 | K11: Reconciliation ALREADY auto reconciled | M11: =COUNTIF(RECONCILIATION_REPORT!B:B,SP_INVOICE_REPORT!C11) -> 3
A12: 25569 | C12: 27086473 | E12: 0 | F12: { } | G12: 34.12 | H12: SP_INVOICE_ENTRY_STATUS_DISCREPANCY | I12: 507 | K12: Net price discrepancy | M12: =COUNTIF(RECONCILIATION_REPORT!B:B,SP_INVOICE_REPORT!C12) -> 1
A13: 25569 | C13: 27087029 | E13: 0 | F13: { } | G13: 68.25 | H13: SP_INVOICE_ENTRY_STATUS_ALREADY_AUTO_RECONCILED | I13: 507 | K13: Reconciliation ALREADY auto reconciled | M13: =COUNTIF(RECONCILIATION_REPORT!B:B,SP_INVOICE_REPORT!C13) -> 3
... A2371: 25569 | C2371: 28755991 | E2371: 0 | F2371: { } | G2371: 472.5 | H2371: SP_INVOICE_ENTRY_STATUS_UNRESOLVED | I2371: 507 | K2371: No matching reconciliations found | M2371: =COUNTIF(RECONCILIATION_REPORT!B:B,SP_INVOICE_REPORT!C2371) -> 1

Sheet RECONCILIATION_REPORT
A1: id | B1: bookingId | C1: fulfilmentId | D1: bookingCreationDate | E1: experienceDate | F1: fulfilmentStatus | G1: tgid | H1: tid | I1: experienceName | J1: tourName | K1: billingEntityName | L1: beId | M1: vendorName | N1: vid | O1: fulfilmentMethod | P1: paymentMethod | Q1: primaryGuestName | R1: persons | S1: paymentBasis | T1: spBookingRefNumber | U1: internalPaymentRefNumber | V1: status | W1: actor | X1: version | Y1: createdAt | Z1: updatedAt | AA1: currency | AB1: headoutSellingPrice | AC1: netPrice | AD1: extraCharges | AE1: partiallyFulfilled | AF1: bookingStatus | AG1: finalVendorId | AH1: chargedLoss | AI1: errorTeamAttribution | AJ1: errorBucket | AK1: comments | AL1: reconcileManually | AM1: reason | AN1: bnpl | AO1: insurance | AP1: spNet | AQ1: invoiceId | AR1: totalAmountPayable | AS1: netPricePayable | AT1: totalAmountPaid | AU1: concatUtr | AV1: concatDateOfPayment | AW1: enteredAmountPaid | AX1: enteredUtr | AY1: enteredDateOfPayment | AZ1: disputeStatus | BA1: totalDisputeAmount | BB1: balanceDisputeAmount | BC1: totalDisputeAdjustmentAmount | BD1: concatDisputeAmountAdjustedInvoiceId | BE1: totalDiscrepancyAmount | BF1: enteredDisputeAdjustment | BG1: enteredDisputeAmountAdjustedInvoiceId | BH1: enteredDiscrepancyAmount | BI1: reconciledNetPrice | BJ1: adult_count | BK1: adult_unit_price | BL1: adult_price_net | BM1: child_count | BN1: child_unit_price | BO1: child_price_net | BP1: general_count | BQ1: general_unit_price | BR1: general_price_net
A2: reconciliation_1525919376221305 | B2: 27063716 | C2: 13792310 | D2: 45901.212 | E2: 45907 | F2: FAILED | G2: 16051 | H2: 27596 | I2: General Admission Open Dated | K2: Louvre Abu Dhabi | L2: 507 | M2: Louvre Mueseum_Abu Dhabi | N2: 1488 | O2: SELENIUM | P2: PORTAL_DEPOSIT | Q2: Akash Jay Krishnan | R2: { "totalCount": 3, "personList": [{ "count": 3, "type": "ADULT", "priceNet": 34.13 }] } | S2: DATE_OF_BOOKING | U2: TODO | V2: RECONCILIATION_STATUS_PENDING | W2: RECON | X2: 3 | Y2: 45901.212 | Z2: 45901.869 | AA2: AED | AB2: 135 | AC2: 102.39 | AD2: { } | AE2: FALSE | AF2: COMPLETED | AH2: FALSE | AL2: FALSE | AM2: Reconciliation ALREADY auto reconciled | AZ2: NONE | BJ2: 3 | BK2: 34.13 | BL2: 102.39
A3: reconciliation_16658292957344 | B3: 27063716 | C3: 13797312 | D3: 45901.504 | E3: 45907 | F3: FAILED | G3: 16051 | H3: 27596 | I3: General Admission Open Dated | K3: Louvre Abu Dhabi | L3: 507 | M3: Louvre Mueseum_Abu Dhabi | N3: 1488 | O3: SELENIUM | P3: PORTAL_DEPOSIT | Q3: Akash Jay Krishnan | R3: { "totalCount": 3, "personList": [{ "count": 3, "type": "ADULT", "priceNet": 34.13 }] } | S3: DATE_OF_BOOKING | U3: TODO | V3: RECONCILIATION_STATUS_PENDING | W3: RECON | X3: 3 | Y3: 45901.504 | Z3: 45901.869 | AA3: AED | AB3: 135 | AC3: 102.39 | AD3: { } | AE3: FALSE | AF3: COMPLETED | AH3: FALSE | AL3: FALSE | AM3: Reconciliation ALREADY auto reconciled | AZ3: NONE | BJ3: 3 | BK3: 34.13 | BL3: 102.39
A4: reconciliation_18266063789754 | B4: 27063716 | C4: 13802649 | D4: 45901.796 | E4: 45907 | F4: FAILED | G4: 16051 | H4: 27596 | I4: General Admission Open Dated | K4: Louvre Abu Dhabi | L4: 507 | M4: Louvre Mueseum_Abu Dhabi | N4: 1488 | O4: SELENIUM | P4: PORTAL_DEPOSIT | Q4: Akash Jay Krishnan | R4: { "totalCount": 3, "personList": [{ "count": 3, "type": "ADULT", "priceNet": 34.13 }] } | S4: DATE_OF_BOOKING | U4: TODO | V4: RECONCILIATION_STATUS_PENDING | W4: RECON | X4: 3 | Y4: 45901.796 | Z4: 45901.869 | AA4: AED | AB4: 135 | AC4: 102.39 | AD4: { } | AE4: FALSE | AF4: COMPLETED | AH4: FALSE | AL4: FALSE | AM4: Reconciliation ALREADY auto reconciled | AZ4: NONE | BJ4: 3 | BK4: 34.13 | BL4: 102.39
A5: reconciliation_20237438353024 | B5: 27063716 | C5: 13798076 | D5: 45901.546 | E5: 45907 | F5: FAILED | G5: 16051 | H5: 27596 | I5: General Admission Open Dated | K5: Louvre Abu Dhabi | L5: 507 | M5: Louvre Mueseum_Abu Dhabi | N5: 1488 | O5: SELENIUM | P5: PORTAL_DEPOSIT | Q5: Akash Jay Krishnan | R5: { "totalCount": 3, "personList": [{ "count": 3, "type": "ADULT", "priceNet": 34.13 }] } | S5: DATE_OF_BOOKING | U5: TODO | V5: RECONCILIATION_STATUS_PENDING | W5: RECON | X5: 3 | Y5: 45901.546 | Z5: 45901.869 | AA5: AED | AB5: 135 | AC5: 102.39 | AD5: { } | AE5: FALSE | AF5: COMPLETED | AH5: FALSE | AL5: FALSE | AM5: Reconciliation ALREADY auto reconciled | AZ5: NONE | BJ5: 3 | BK5: 34.13 | BL5: 102.39
A6: reconciliation_203569533027365 | B6: 27063716 | C6: 13798860 | D6: 45901.587 | E6: 45907 | F6: FAILED | G6: 16051 | H6: 27596 | I6: General Admission Open Dated | K6: Louvre Abu Dhabi | L6: 507 | M6: Louvre Mueseum_Abu Dhabi | N6: 1488 | O6: SELENIUM | P6: PORTAL_DEPOSIT | Q6: Akash Jay Krishnan | R6: { "totalCount": 3, "personList": [{ "count": 3, "type": "ADULT", "priceNet": 34.13 }] } | S6: DATE_OF_BOOKING | U6: TODO | V6: RECONCILIATION_STATUS_PENDING | W6: RECON | X6: 3 | Y6: 45901.587 | Z6: 45901.869 | AA6: AED | AB6: 135 | AC6: 102.39 | AD6: { } | AE6: FALSE | AF6: COMPLETED | AH6: FALSE | AL6: FALSE | AM6: Reconciliation ALREADY auto reconciled | AZ6: NONE | BJ6: 3 | BK6: 34.13 | BL6: 102.39
A7: reconciliation_207180278419249 | B7: 27063716 | C7: 13799622 | D7: 45901.629 | E7: 45907 | F7: FAILED | G7: 16051 | H7: 27596 | I7: General Admission Open Dated | K7: Louvre Abu Dhabi | L7: 507 | M7: Louvre Mueseum_Abu Dhabi | N7: 1488 | O7: SELENIUM | P7: PORTAL_DEPOSIT | Q7: Akash Jay Krishnan | R7: { "totalCount": 3, "personList": [{ "count": 3, "type": "ADULT", "priceNet": 34.13 }] } | S7: DATE_OF_BOOKING | U7: TODO | V7: RECONCILIATION_STATUS_PENDING | W7: RECON | X7: 3 | Y7: 45901.629 | Z7: 45901.869 | AA7: AED | AB7: 135 | AC7: 102.39 | AD7: { } | AE7: FALSE | AF7: COMPLETED | AH7: FALSE | AL7: FALSE | AM7: Reconciliation ALREADY auto reconciled | AZ7: NONE | BJ7: 3 | BK7: 34.13 | BL7: 102.39
A8: reconciliation_210812054231475 | B8: 27063716 | C8: 13800383 | D8: 45901.671 | E8: 45907 | F8: FAILED | G8: 16051 | H8: 27596 | I8: General Admission Open Dated | K8: Louvre Abu Dhabi | L8: 507 | M8: Louvre Mueseum_Abu Dhabi | N8: 1488 | O8: SELENIUM | P8: PORTAL_DEPOSIT | Q8: Akash Jay Krishnan | R8: { "totalCount": 3, "personList": [{ "count": 3, "type": "ADULT", "priceNet": 34.13 }] } | S8: DATE_OF_BOOKING | U8: TODO | V8: RECONCILIATION_STATUS_PENDING | W8: RECON | X8: 3 | Y8: 45901.671 | Z8: 45901.869 | AA8: AED | AB8: 135 | AC8: 102.39 | AD8: { } | AE8: FALSE | AF8: COMPLETED | AH8: FALSE | AL8: FALSE | AM8: Reconciliation ALREADY auto reconciled | AZ8: NONE | BJ8: 3 | BK8: 34.13 | BL8: 102.39
A9: reconciliation_214365181316922 | B9: 27063716 | C9: 13801147 | D9: 45901.712 | E9: 45907 | F9: FAILED | G9: 16051 | H9: 27596 | I9: General Admission Open Dated | K9: Louvre Abu Dhabi | L9: 507 | M9: Louvre Mueseum_Abu Dhabi | N9: 1488 | O9: SELENIUM | P9: PORTAL_DEPOSIT | Q9: Akash Jay Krishnan | R9: { "totalCount": 3, "personList": [{ "count": 3, "type": "ADULT", "priceNet": 34.13 }] } | S9: DATE_OF_BOOKING | U9: TODO | V9: RECONCILIATION_STATUS_PENDING | W9: RECON | X9: 3 | Y9: 45901.712 | Z9: 45901.869 | AA9: AED | AB9: 135 | AC9: 102.39 | AD9: { } | AE9: FALSE | AF9: COMPLETED | AH9: FALSE | AL9: FALSE | AM9: Reconciliation ALREADY auto reconciled | AZ9: NONE | BJ9: 3 | BK9: 34.13 | BL9: 102.39
A10: reconciliation_215680546474750 | B10: 27063716 | C10: 13791968 | D10: 45901.157 | E10: 45907 | F10: FAILED | G10: 16051 | H10: 27596 | I10: General Admission Open Dated | K10: Louvre Abu Dhabi | L10: 507 | M10: Louvre Mueseum_Abu Dhabi | N10: 1488 | O10: SELENIUM | P10: PORTAL_DEPOSIT | Q10: Akash Jay Krishnan | R10: { "totalCount": 3, "personList": [{ "count": 3, "type": "ADULT", "priceNet": 34.13 }] } | S10: DATE_OF_BOOKING | U10: TODO | V10: RECONCILIATION_STATUS_PENDING | W10: RECON | X10: 3 | Y10: 45901.157 | Z10: 45901.869 | AA10: AED | AB10: 135 | AC10: 102.39 | AD10: { } | AE10: FALSE | AF10: COMPLETED | AH10: FALSE | AL10: FALSE | AM10: Reconciliation ALREADY auto reconciled | AZ10: NONE | BJ10: 3 | BK10: 34.13 | BL10: 102.39
A11: reconciliation_21894286540508 | B11: 27063716 | C11: 13803466 | D11: 45901.838 | E11: 45907 | F11: FAILED | G11: 16051 | H11: 27596 | I11: General Admission Open Dated | K11: Louvre Abu Dhabi | L11: 507 | M11: Louvre Mueseum_Abu Dhabi | N11: 1488 | O11: SELENIUM | P11: PORTAL_DEPOSIT | Q11: Akash Jay Krishnan | R11: { "totalCount": 3, "personList": [{ "count": 3, "type": "ADULT", "priceNet": 34.13 }] } | S11: DATE_OF_BOOKING | U11: TODO | V11: RECONCILIATION_STATUS_PENDING | W11: RECON | X11: 3 | Y11: 45901.838 | Z11: 45901.869 | AA11: AED | AB11: 135 | AC11: 102.39 | AD11: { } | AE11: FALSE | AF11: COMPLETED | AH11: FALSE | AL11: FALSE | AM11: Reconciliation ALREADY auto reconciled | AZ11: NONE | BJ11: 3 | BK11: 34.13 | BL11: 102.39
A12: reconciliation_224111901198644 | B12: 27063716 | C12: 13792613 | D12: 45901.254 | E12: 45907 | F12: FAILED | G12: 16051 | H12: 27596 | I12: General Admission Open Dated | K12: Louvre Abu Dhabi | L12: 507 | M12: Louvre Mueseum_Abu Dhabi | N12: 1488 | O12: SELENIUM | P12: PORTAL_DEPOSIT | Q12: Akash Jay Krishnan | R12: { "totalCount": 3, "personList": [{ "count": 3, "type": "ADULT", "priceNet": 34.13 }] } | S12: DATE_OF_BOOKING | U12: TODO | V12: RECONCILIATION_STATUS_PENDING | W12: RECON | X12: 3 | Y12: 45901.254 | Z12: 45901.869 | AA12: AED | AB12: 135 | AC12: 102.39 | AD12: { } | AE12: FALSE | AF12: COMPLETED | AH12: FALSE | AL12: FALSE | AM12: Reconciliation ALREADY auto reconciled | AZ12: NONE | BJ12: 3 | BK12: 34.13 | BL12: 102.39
A13: reconciliation_227700100977044 | B13: 27063716 | C13: 13793066 | D13: 45901.296 | E13: 45907 | F13: FAILED | G13: 16051 | H13: 27596 | I13: General Admission Open Dated | K13: Louvre Abu Dhabi | L13: 507 | M13: Louvre Mueseum_Abu Dhabi | N13: 1488 | O13: SELENIUM | P13: PORTAL_DEPOSIT | Q13: Akash Jay Krishnan | R13: { "totalCount": 3, "personList": [{ "count": 3, "type": "ADULT", "priceNet": 34.13 }] } | S13: DATE_OF_BOOKING | U13: TODO | V13: RECONCILIATION_STATUS_PENDING | W13: RECON | X13: 3 | Y13: 45901.296 | Z13: 45901.869 | AA13: AED | AB13: 135 | AC13: 102.39 | AD13: { } | AE13: FALSE | AF13: COMPLETED | AH13: FALSE | AL13: FALSE | AM13: Reconciliation ALREADY auto reconciled | AZ13: NONE | BJ13: 3 | BK13: 34.13 | BL13: 102.39
... A15: reconciliation_242166492675003 | B15: 27063716 | C15: 13796543 | D15: 45901.463 | E15: 45907 | F15: FAILED | G15: 16051 | H15: 27596 | I15: General Admission Open Dated | K15: Louvre Abu Dhabi | L15: 507 | M15: Louvre Mueseum_Abu Dhabi | N15: 1488 | O15: SELENIUM | P15: PORTAL_DEPOSIT | Q15: Akash Jay Krishnan | R15: { "totalCount": 3, "personList": [{ "count": 3, "type": "ADULT", "priceNet": 34.13 }] } | S15: DATE_OF_BOOKING | U15: TODO | V15: RECONCILIATION_STATUS_PENDING | W15: RECON | X15: 3 | Y15: 45901.463 | Z15: 45901.869 | AA15: AED | AB15: 135 | AC15: 102.39 | AD15: { } | AE15: FALSE | AF15: COMPLETED | AH15: FALSE | AL15: FALSE | AM15: Reconciliation ALREADY auto reconciled | AZ15: NONE | BJ15: 3 | BK15: 34.13 | BL15: 102.39
A16: reconciliation_24600200396296 | B16: 27063716 | C16: 13804039 | D16: 45901.869 | E16: 45907 | F16: SUCCESS | G16: 16051 | H16: 27596 | I16: General Admission Open Dated | K16: Louvre Abu Dhabi | L16: 507 | M16: Louvre Mueseum_Abu Dhabi | N16: 1488 | O16: MANUAL | P16: PORTAL_DEPOSIT | Q16: Akash Jay Krishnan | R16: { "totalCount": 3, "personList": [{ "count": 3, "type": "ADULT", "priceNet": 34.13 }] } | S16: DATE_OF_BOOKING | T16: ORD-2546696-Z7V8M6 | U16: TODO | V16: RECONCILIATION_STATUS_AUTO_RECONCILED | W16: RECON | X16: 2 | Y16: 45901.869 | Z16: 45902.275 | AA16: AED | AB16: 135 | AC16: 102.39 | AD16: { } | AE16: FALSE | AF16: COMPLETED | AH16: FALSE | AL16: FALSE | AM16: Reconciliation ALREADY auto reconciled | AZ16: NONE | BJ16: 3 | BK16: 34.13 | BL16: 102.39
A17: reconciliation_5861759714950 | B17: 27063716 | C17: 13794795 | D17: 45901.379 | E17: 45907 | F17: FAILED | G17: 16051 | H17: 27596 | I17: General Admission Open Dated | K17: Louvre Abu Dhabi | L17: 507 | M17: Louvre Mueseum_Abu Dhabi | N17: 1488 | O17: SELENIUM | P17: PORTAL_DEPOSIT | Q17: Akash Jay Krishnan | R17: { "totalCount": 3, "personList": [{ "count": 3, "type": "ADULT", "priceNet": 34.13 }] } | S17: DATE_OF_BOOKING | U17: TODO | V17: RECONCILIATION_STATUS_PENDING | W17: RECON | X17: 3 | Y17: 45901.379 | Z17: 45901.869 | AA17: AED | AB17: 135 | AC17: 102.39 | AD17: { } | AE17: FALSE | AF17: COMPLETED | AH17: FALSE | AL17: FALSE | AM17: Reconciliation ALREADY auto reconciled | AZ17: NONE | BJ17: 3 | BK17: 34.13 | BL17: 102.39
A18: reconciliation_9463441904114 | B18: 27063716 | C18: 13795703 | D18: 45901.421 | E18: 45907 | F18: FAILED | G18: 16051 | H18: 27596 | I18: General Admission Open Dated | K18: Louvre Abu Dhabi | L18: 507 | M18: Louvre Mueseum_Abu Dhabi | N18: 1488 | O18: SELENIUM | P18: PORTAL_DEPOSIT | Q18: Akash Jay Krishnan | R18: { "totalCount": 3, "personList": [{ "count": 3, "type": "ADULT", "priceNet": 34.13 }] } | S18: DATE_OF_BOOKING | U18: TODO | V18: RECONCILIATION_STATUS_PENDING | W18: RECON | X18: 3 | Y18: 45901.421 | Z18: 45901.869 | AA18: AED | AB18: 135 | AC18: 102.39 | AD18: { } | AE18: FALSE | AF18: COMPLETED | AH18: FALSE | AL18: FALSE | AM18: Reconciliation ALREADY auto reconciled | AZ18: NONE | BJ18: 3 | BK18: 34.13 | BL18: 102.39
A19: reconciliation_20261488274821 | B19: 27070292 | C19: 13798089 | D19: 45901.546 | E19: 45902 | F19: FAILED | G19: 16051 | H19: 27596 | I19: General Admission Open Dated | K19: Louvre Abu Dhabi | L19: 507 | M19: Louvre Mueseum_Abu Dhabi | N19: 1488 | O19: SELENIUM | P19: PORTAL_DEPOSIT | Q19: Edward Theodor Danescu | R19: { "totalCount": 2, "personList": [{ "count": 2, "type": "ADULT", "priceNet": 34.13 }] } | S19: DATE_OF_BOOKING | U19: TODO | V19: RECONCILIATION_STATUS_PENDING | W19: RECON | X19: 3 | Y19: 45901.546 | Z19: 45901.639 | AA19: AED | AB19: 90 | AC19: 68.26 | AD19: { } | AE19: FALSE | AF19: COMPLETED | AH19: FALSE | AL19: FALSE | AM19: Reconciliation ALREADY auto reconciled | AZ19: NONE | BJ19: 2 | BK19: 34.13 | BL19: 68.26
A20: reconciliation_203592560424368 | B20: 27070292 | C20: 13798865 | D20: 45901.588 | E20: 45902 | F20: FAILED | G20: 16051 | H20: 27596 | I20: General Admission Open Dated | K20: Louvre Abu Dhabi | L20: 507 | M20: Louvre Mueseum_Abu Dhabi | N20: 1488 | O20: SELENIUM | P20: PORTAL_DEPOSIT | Q20: Edward Theodor Danescu | R20: { "totalCount": 2, "personList": [{ "count": 2, "type": "ADULT", "priceNet": 34.13 }] } | S20: DATE_OF_BOOKING | U20: TODO | V20: RECONCILIATION_STATUS_PENDING | W20: RECON | X20: 3 | Y20: 45901.588 | Z20: 45901.639 | AA20: AED | AB20: 90 | AC20: 68.26 | AD20: { } | AE20: FALSE | AF20: COMPLETED | AH20: FALSE | AL20: FALSE | AM20: Reconciliation ALREADY auto reconciled | AZ20: NONE | BJ20: 2 | BK20: 34.13 | BL20: 68.26
A21: reconciliation_208053534841590 | B21: 27070292 | C21: 13799814 | D21: 45901.639 | E21: 45902 | F21: SUCCESS | G21: 16051 | H21: 27596 | I21: General Admission Open Dated | K21: Louvre Abu Dhabi | L21: 507 | M21: Louvre Mueseum_Abu Dhabi | N21: 1488 | O21: MANUAL | P21: PORTAL_DEPOSIT | Q21: Edward Theodor Danescu | R21: { "totalCount": 2, "personList": [{ "count": 2, "type": "ADULT", "priceNet": 34.13 }] } | S21: DATE_OF_BOOKING | T21: ORD-2546623-L6P1Q5 | U21: TODO | V21: RECONCILIATION_STATUS_AUTO_RECONCILED | W21: RECON | X21: 2 | Y21: 45901.639 | Z21: 45902.275 | AA21: AED | AB21: 90 | AC21: 68.26 | AD21: { } | AE21: FALSE | AF21: COMPLETED | AH21: FALSE | AL21: FALSE | AM21: Reconciliation ALREADY auto reconciled | AZ21: NONE | BJ21: 2 | BK21: 34.13 | BL21: 68.26
A22: reconciliation_245289225839154 | B22: 27070292 | C22: 13797228 | D22: 45901.499 | E22: 45902 | F22: FAILED | G22: 16051 | H22: 27596 | I22: General Admission Open Dated | K22: Louvre Abu Dhabi | L22: 507 | M22: Louvre Mueseum_Abu Dhabi | N22: 1488 | O22: SELENIUM | P22: PORTAL_DEPOSIT | Q22: Edward Theodor Danescu | R22: { "totalCount": 2, "personList": [{ "count": 2, "type": "ADULT", "priceNet": 34.13 }] } | S22: DATE_OF_BOOKING | U22: TODO | V22: RECONCILIATION_STATUS_PENDING | W22: RECON | X22: 3 | Y22: 45901.499 | Z22: 45901.639 | AA22: AED | AB22: 90 | AC22: 68.26 | AD22: { } | AE22: FALSE | AF22: COMPLETED | AH22: FALSE | AL22: FALSE | AM22: Reconciliation ALREADY auto reconciled | AZ22: NONE | BJ22: 2 | BK22: 34.13 | BL22: 68.26
A23: reconciliation_3905271371704 | B23: 27070292 | C23: 13799627 | D23: 45901.629 | E23: 45902 | F23: FAILED | G23: 16051 | H23: 27596 | I23: General Admission Open Dated | K23: Louvre Abu Dhabi | L23: 507 | M23: Louvre Mueseum_Abu Dhabi | N23: 1488 | O23: SELENIUM | P23: PORTAL_DEPOSIT | Q23: Edward Theodor Danescu | R23: { "totalCount": 2, "personList": [{ "count": 2, "type": "ADULT", "priceNet": 34.13 }] } | S23: DATE_OF_BOOKING | U23: TODO | V23: RECONCILIATION_STATUS_PENDING | W23: RECON | X23: 3 | Y23: 45901.629 | Z23: 45901.639 | AA23: AED | AB23: 90 | AC23: 68.26 | AD23: { } | AE23: FALSE | AF23: COMPLETED | AH23: FALSE | AL23: FALSE | AM23: Reconciliation ALREADY auto reconciled | AZ23: NONE | BJ23: 2 | BK23: 34.13 | BL23: 68.26
A24: reconciliation_11090198195300 | B24: 27070478 | C24: 13801153 | D24: 45901.713 | E24: 45907 | F24: FAILED | G24: 14619 | H24: 27596 | I24: General Admission Open Dated | K24: Louvre Abu Dhabi | L24: 507 | M24: Louvre Mueseum_Abu Dhabi | N24: 1488 | O24: SELENIUM | P24: PORTAL_DEPOSIT | Q24: Inesa Alikhanyan | R24: { "totalCount": 2, "personList": [{ "count": 2, "type": "ADULT", "priceNet": 34.13 }] } | S24: DATE_OF_BOOKING | U24: TODO | V24: RECONCILIATION_STATUS_PENDING | W24: RECON | X24: 3 | Y24: 45901.713 | Z24: 45901.824 | AA24: AED | AB24: 90 | AC24: 68.26 | AD24: { } | AE24: FALSE | AF24: COMPLETED | AH24: FALSE | AL24: FALSE | AM24: Net price discrepancy | AZ24: NONE | BJ24: 2 | BK24: 34.13 | BL24: 68.26
A25: reconciliation_17028536426481 | B25: 27070478 | C25: 13797405 | D25: 45901.508 | E25: 45907 | F25: FAILED | G25: 14619 | H25: 27596 | I25: General Admission Open Dated | K25: Louvre Abu Dhabi | L25: 507 | M25: Louvre Mueseum_Abu Dhabi | N25: 1488 | O25: SELENIUM | P25: PORTAL_DEPOSIT | Q25: Inesa Alikhanyan | R25: { "totalCount": 2, "personList": [{ "count": 2, "type": "ADULT", "priceNet": 34.13 }] } | S25: DATE_OF_BOOKING | U25: TODO | V25: RECONCILIATION_STATUS_PENDING | W25: RECON | X25: 3 | Y25: 45901.508 | Z25: 45901.824 | AA25: AED | AB25: 90 | AC25: 68.26 | AD25: { } | AE25: FALSE | AF25: COMPLETED | AH25: FALSE | AL25: FALSE | AM25: Net price discrepancy | AZ25: NONE | BJ25: 2 | BK25: 34.13 | BL25: 68.26
A26: reconciliation_203592579461615 | B26: 27070478 | C26: 13798866 | D26: 45901.588 | E26: 45907 | F26: FAILED | G26: 14619 | H26: 27596 | I26: General Admission Open Dated | K26: Louvre Abu Dhabi | L26: 507 | M26: Louvre Mueseum_Abu Dhabi | N26: 1488 | O26: SELENIUM | P26: PORTAL_DEPOSIT | Q26: Inesa Alikhanyan | R26: { "totalCount": 2, "personList": [{ "count": 2, "type": "ADULT", "priceNet": 34.13 }] } | S26: DATE_OF_BOOKING | U26: TODO | V26: RECONCILIATION_STATUS_PENDING | W26: RECON | X26: 3 | Y26: 45901.588 | Z26: 45901.824 | AA26: AED | AB26: 90 | AC26: 68.26 | AD26: { } | AE26: FALSE | AF26: COMPLETED | AH26: FALSE | AL26: FALSE | AM26: Net price discrepancy | AZ26: NONE | BJ26: 2 | BK26: 34.13 | BL26: 68.26
A27: reconciliation_210834598683758 | B27: 27070478 | C27: 13800387 | D27: 45901.671 | E27: 45907 | F27: FAILED | G27: 14619 | H27: 27596 | I27: General Admission Open Dated | K27: Louvre Abu Dhabi | L27: 507 | M27: Louvre Mueseum_Abu Dhabi | N27: 1488 | O27: SELENIUM | P27: PORTAL_DEPOSIT | Q27: Inesa Alikhanyan | R27: { "totalCount": 2, "personList": [{ "count": 2, "type": "ADULT", "priceNet": 34.13 }] } | S27: DATE_OF_BOOKING | U27: TODO | V27: RECONCILIATION_STATUS_PENDING | W27: RECON | X27: 3 | Y27: 45901.671 | Z27: 45901.824 | AA27: AED | AB27: 90 | AC27: 68.26 | AD27: { } | AE27: FALSE | AF27: COMPLETED | AH27: FALSE | AL27: FALSE | AM27: Net price discrepancy | AZ27: NONE | BJ27: 2 | BK27: 34.13 | BL27: 68.26
A28: reconciliation_218101659143509 | B28: 27070478 | C28: 13801905 | D28: 45901.756 | E28: 45907 | F28: FAILED | G28: 14619 | H28: 27596 | I28: General Admission Open Dated | K28: Louvre Abu Dhabi | L28: 507 | M28: Louvre Mueseum_Abu Dhabi | N28: 1488 | O28: SELENIUM | P28: PORTAL_DEPOSIT | Q28: Inesa Alikhanyan | R28: { "totalCount": 2, "personList": [{ "count": 2, "type": "ADULT", "priceNet": 34.13 }] } | S28: DATE_OF_BOOKING | U28: TODO | V28: RECONCILIATION_STATUS_PENDING | W28: RECON | X28: 3 | Y28: 45901.755 | Z28: 45901.824 | AA28: AED | AB28: 90 | AC28: 68.26 | AD28: { } | AE28: FALSE | AF28: COMPLETED | AH28: FALSE | AL28: FALSE | AM28: Net price discrepancy | AZ28: NONE | BJ28: 2 | BK28: 34.13 | BL28: 68.26
A29: reconciliation_221584146498982 | B29: 27070478 | C29: 13802658 | D29: 45901.796 | E29: 45907 | F29: FAILED | G29: 14619 | H29: 27596 | I29: General Admission Open Dated | K29: Louvre Abu Dhabi | L29: 507 | M29: Louvre Mueseum_Abu Dhabi | N29: 1488 | O29: SELENIUM | P29: PORTAL_DEPOSIT | Q29: Inesa Alikhanyan | R29: { "totalCount": 2, "personList": [{ "count": 2, "type": "ADULT", "priceNet": 34.13 }] } | S29: DATE_OF_BOOKING | U29: TODO | V29: RECONCILIATION_STATUS_PENDING | W29: RECON | X29: 3 | Y29: 45901.796 | Z29: 45901.824 | AA29: AED | AB29: 90 | AC29: 68.26 | AD29: { } | AE29: FALSE | AF29: COMPLETED | AH29: FALSE | AL29: FALSE | AM29: Net price discrepancy | AZ29: NONE | BJ29: 2 | BK29: 34.13 | BL29: 68.26
A30: reconciliation_223984442949738 | B30: 27070478 | C30: 13803170 | D30: 45901.824 | E30: 45907 | F30: SUCCESS | G30: 14619 | H30: 27596 | I30: General Admission Open Dated | K30: Louvre Abu Dhabi | L30: 507 | M30: Louvre Mueseum_Abu Dhabi | N30: 1488 | O30: MANUAL | P30: PORTAL_DEPOSIT | Q30: Inesa Alikhanyan | R30: { "totalCount": 2, "personList": [{ "count": 2, "type": "ADULT", "priceNet": 34.13 }] } | S30: DATE_OF_BOOKING | T30: ORD-2546649-R3Y6F2 | U30: TODO | V30: RECONCILIATION_STATUS_DISCREPANCY | W30: RECON | X30: 2 | Y30: 45901.824 | Z30: 45902.275 | AA30: AED | AB30: 90 | AC30: 68.26 | AD30: { } | AE30: FALSE | AF30: COMPLETED | AH30: FALSE | AL30: FALSE | AM30: Net price discrepancy | AZ30: NONE | BJ30: 2 | BK30: 34.13 | BL30: 68.26
A31: reconciliation_249314257888654 | B31: 27070478 | C31: 13798090 | D31: 45901.546 | E31: 45907 | F31: FAILED | G31: 14619 | H31: 27596 | I31: General Admission Open Dated | K31: Louvre Abu Dhabi | L31: 507 | M31: Louvre Mueseum_Abu Dhabi | N31: 1488 | O31: SELENIUM | P31: PORTAL_DEPOSIT | Q31: Inesa Alikhanyan | R31: { "totalCount": 2, "personList": [{ "count": 2, "type": "ADULT", "priceNet": 34.13 }] } | S31: DATE_OF_BOOKING | U31: TODO | V31: RECONCILIATION_STATUS_PENDING | W31: RECON | X31: 3 | Y31: 45901.546 | Z31: 45901.824 | AA31: AED | AB31: 90 | AC31: 68.26 | AD31: { } | AE31: FALSE | AF31: COMPLETED | AH31: FALSE | AL31: FALSE | AM31: Net price discrepancy | AZ31: NONE | BJ31: 2 | BK31: 34.13 | BL31: 68.26
A32: reconciliation_3905769190387 | B32: 27070478 | C32: 13799630 | D32: 45901.629 | E32: 45907 | F32: FAILED | G32: 14619 | H32: 27596 | I32: General Admission Open Dated | K32: Louvre Abu Dhabi | L32: 507 | M32: Louvre Mueseum_Abu Dhabi | N32: 1488 | O32: SELENIUM | P32: PORTAL_DEPOSIT | Q32: Inesa Alikhanyan | R32: { "totalCount": 2, "personList": [{ "count": 2, "type": "ADULT", "priceNet": 34.13 }] } | S32: DATE_OF_BOOKING | U32: TODO | V32: RECONCILIATION_STATUS_PENDING | W32: RECON | X32: 3 | Y32: 45901.629 | Z32: 45901.824 | AA32: AED | AB32: 90 | AC32: 68.26 | AD32: { } | AE32: FALSE | AF32: COMPLETED | AH32: FALSE | AL32: FALSE | AM32: Net price discrepancy | AZ32: NONE | BJ32: 2 | BK32: 34.13 | BL32: 68.26
A33: reconciliation_18293591235479 | B33: 27075844 | C33: 13802664 | D33: 45901.796 | E33: 45902 | F33: FAILED | G33: 14619 | H33: 27596 | I33: General Admission Open Dated | K33: Louvre Abu Dhabi | L33: 507 | M33: Louvre Mueseum_Abu Dhabi | N33: 1488 | O33: SELENIUM | P33: PORTAL_DEPOSIT | Q33: Ioanna stamouli | R33: { "totalCount": 2, "personList": [{ "count": 2, "type": "ADULT", "priceNet": 34.13 }] } | S33: DATE_OF_BOOKING | U33: TODO | V33: RECONCILIATION_STATUS_PENDING | W33: RECON | X33: 3 | Y33: 45901.796 | Z33: 45901.879 | AA33: AED | AB33: 90 | AC33: 68.26 | AD33: { } | AE33: FALSE | AF33: COMPLETED | AH33: FALSE | AL33: FALSE | AM33: Reconciliation ALREADY auto reconciled | AZ33: NONE | BJ33: 2 | BK33: 34.13 | BL33: 68.26
A34: reconciliation_217364686273216 | B34: 27075844 | C34: 13801764 | D34: 45901.747 | E34: 45902 | F34: FAILED | G34: 14619 | H34: 27596 | I34: General Admission Open Dated | K34: Louvre Abu Dhabi | L34: 507 | M34: Louvre Mueseum_Abu Dhabi | N34: 1488 | O34: SELENIUM | P34: PORTAL_DEPOSIT | Q34: Ioanna stamouli | R34: { "totalCount": 2, "personList": [{ "count": 2, "type": "ADULT", "priceNet": 34.13 }] } | S34: DATE_OF_BOOKING | U34: TODO | V34: RECONCILIATION_STATUS_PENDING | W34: RECON | X34: 3 | Y34: 45901.747 | Z34: 45901.879 | AA34: AED | AB34: 90 | AC34: 68.26 | AD34: { } | AE34: FALSE | AF34: COMPLETED | AH34: FALSE | AL34: FALSE | AM34: Reconciliation ALREADY auto reconciled | AZ34: NONE | BJ34: 2 | BK34: 34.13 | BL34: 68.26
A35: reconciliation_225216389714667 | B35: 27075844 | C35: 13803478 | D35: 45901.838 | E35: 45902 | F35: FAILED | G35: 14619 | H35: 27596 | I35: General Admission Open Dated | K35: Louvre Abu Dhabi | L35: 507 | M35: Louvre Mueseum_Abu Dhabi | N35: 1488 | O35: SELENIUM | P35: PORTAL_DEPOSIT | Q35: Ioanna stamouli | R35: { "totalCount": 2, "personList": [{ "count": 2, "type": "ADULT", "priceNet": 34.13 }] } | S35: DATE_OF_BOOKING | U35: TODO | V35: RECONCILIATION_STATUS_PENDING | W35: RECON | X35: 3 | Y35: 45901.838 | Z35: 45901.879 | AA35: AED | AB35: 90 | AC35: 68.26 | AD35: { } | AE35: FALSE | AF35: COMPLETED | AH35: FALSE | AL35: FALSE | AM35: Reconciliation ALREADY auto reconciled | AZ35: NONE | BJ35: 2 | BK35: 34.13 | BL35: 68.26
A36: reconciliation_25478958673280 | B36: 27075844 | C36: 13804228 | D36: 45901.879 | E36: 45902 | F36: SUCCESS | G36: 14619 | H36: 27596 | I36: General Admission Open Dated | K36: Louvre Abu Dhabi | L36: 507 | M36: Louvre Mueseum_Abu Dhabi | N36: 1488 | O36: MANUAL | P36: PORTAL_DEPOSIT | Q36: Ioanna stamouli | R36: { "totalCount": 2, "personList": [{ "count": 2, "type": "ADULT", "priceNet": 34.13 }] } | S36: DATE_OF_BOOKING | T36: ORD-2546710-B0F7D3 | U36: TODO | V36: RECONCILIATION_STATUS_AUTO_RECONCILED | W36: RECON | X36: 2 | Y36: 45901.879 | Z36: 45903.345 | AA36: AED | AB36: 90 | AC36: 68.26 | AD36: { } | AE36: FALSE | AF36: COMPLETED | AH36: FALSE | AL36: FALSE | AM36: Reconciliation ALREADY auto reconciled | AZ36: NONE | BJ36: 2 | BK36: 34.13 | BL36: 68.26
A37: reconciliation_235364756125429 | B37: 27079427 | C37: 13805198 | D37: 45901.955 | E37: 45912 | F37: SUCCESS | G37: 16051 | H37: 27596 | I37: General Admission Open Dated | K37: Louvre Abu Dhabi | L37: 507 | M37: Louvre Mueseum_Abu Dhabi | N37: 1488 | O37: MANUAL | P37: PORTAL_DEPOSIT | Q37: Andrei Ivankou | R37: { "totalCount": 2, "personList": [{ "count": 2, "type": "ADULT", "priceNet": 34.13 }] } | S37: DATE_OF_BOOKING | T37: ORD-2546715-H8M7B5 | U37: TODO | V37: RECONCILIATION_STATUS_AUTO_RECONCILED | W37: RECON | X37: 2 | Y37: 45901.955 | Z37: 45903.345 | AA37: AED | AB37: 90 | AC37: 68.26 | AD37: { } | AE37: FALSE | AF37: COMPLETED | AH37: FALSE | AL37: FALSE | AM37: Reconciliation ALREADY auto reconciled | AZ37: NONE | BJ37: 2 | BK37: 34.13 | BL37: 68.26
A38: reconciliation_28603219558905 | B38: 27079427 | C38: 13804759 | D38: 45901.915 | E38: 45912 | F38: FAILED | G38: 16051 | H38: 27596 | I38: General Admission Open Dated | K38: Louvre Abu Dhabi | L38: 507 | M38: Louvre Mueseum_Abu Dhabi | N38: 1488 | O38: SELENIUM | P38: PORTAL_DEPOSIT | Q38: Andrei Ivankou | R38: { "totalCount": 2, "personList": [{ "count": 2, "type": "ADULT", "priceNet": 34.13 }] } | S38: DATE_OF_BOOKING | U38: TODO | V38: RECONCILIATION_STATUS_PENDING | W38: RECON | X38: 3 | Y38: 45901.915 | Z38: 45901.955 | AA38: AED | AB38: 90 | AC38: 68.26 | AD38: { } | AE38: FALSE | AF38: COMPLETED | AH38: FALSE | AL38: FALSE | AM38: Reconciliation ALREADY auto reconciled | AZ38: NONE | BJ38: 2 | BK38: 34.13 | BL38: 68.26
A39: reconciliation_252054199085924 | B39: 27081400 | C39: 13806569 | D39: 45902.148 | E39: 45902 | F39: SUCCESS | G39: 14619 | H39: 27596 | I39: General Admission Open Dated | K39: Louvre Abu Dhabi | L39: 507 | M39: Louvre Mueseum_Abu Dhabi | N39: 1488 | O39: MANUAL | P39: PORTAL_DEPOSIT | Q39: josep seuma lavilla | R39: { "totalCount": 2, "personList": [{ "count": 2, "type": "ADULT", "priceNet": 34.13 }] } | S39: DATE_OF_BOOKING | T39: ORD-2546735-C2Z4W4 | U39: TODO | V39: RECONCILIATION_STATUS_AUTO_RECONCILED | W39: RECON | X39: 2 | Y39: 45902.148 | Z39: 45903.345 | AA39: AED | AB39: 90 | AC39: 68.26 | AD39: { } | AE39: FALSE | AF39: COMPLETED | AH39: FALSE | AL39: FALSE | AM39: Reconciliation ALREADY auto reconciled | AZ39: NONE | BJ39: 2 | BK39: 34.13 | BL39: 68.26
A40: reconciliation_45850829660552 | B40: 27081400 | C40: 13806367 | D40: 45902.115 | E40: 45902 | F40: FAILED | G40: 14619 | H40: 27596 | I40: General Admission Open Dated | K40: Louvre Abu Dhabi | L40: 507 | M40: Louvre Mueseum_Abu Dhabi | N40: 1488 | O40: SELENIUM | P40: PORTAL_DEPOSIT | Q40: josep seuma lavilla | R40: { "totalCount": 2, "personList": [{ "count": 2, "type": "ADULT", "priceNet": 34.13 }] } | S40: DATE_OF_BOOKING | U40: TODO | V40: RECONCILIATION_STATUS_PENDING | W40: RECON | X40: 3 | Y40: 45902.115 | Z40: 45902.148 | AA40: AED | AB40: 90 | AC40: 68.26 | AD40: { } | AE40: FALSE | AF40: COMPLETED | AH40: FALSE | AL40: FALSE | AM40: Reconciliation ALREADY auto reconciled | AZ40: NONE | BJ40: 2 | BK40: 34.13 | BL40: 68.26
A41: reconciliation_259679542622479 | B41: 27082263 | C41: 13807059 | D41: 45902.237 | E41: 45902 | F41: SUCCESS | G41: 33803 | H41: 15344 | I41: LOUVRE ABU DHABI - General Admission | K41: Louvre Abu Dhabi | L41: 507 | M41: Louvre Mueseum_Abu Dhabi | N41: 1488 | O41: MANUAL | P41: PORTAL_DEPOSIT | Q41: Nina Reichenberger | R41: { "totalCount": 4, "personList": [{ "count": 2, "type": "ADULT", "priceNet": 48.75 }, { "count": 2, "type": "CHILD" }] } | S41: DATE_OF_BOOKING | T41: ORD-2546767-W3R9P3 | U41: TODO | V41: RECONCILIATION_STATUS_DISCREPANCY | W41: RECON | X41: 4 | Y41: 45902.237 | Z41: 45903.345 | AA41: AED | AB41: 104 | AC41: 97.5 | AD41: { } | AE41: FALSE | AF41: COMPLETED | AH41: FALSE | AL41: FALSE | AM41: Net price discrepancy | AZ41: NONE | BJ41: 2 | BK41: 48.75 | BL41: 97.5 | BM41: 2 | BN41: 0 | BO41: 0
...
