Workbook

Sheet SP Invoice Report
A1: fulfilmentDate | B1: spBookingRefNumber | C1: bookingId | D1: customerName | E1: totalPax | F1: persons | G1: netPrice | H1: status | I1: beId | J1: paymentMethod | K1: reason | L1: Ticket id | M1: Currency | N1: count
A2: 25569 | C2: 27697547 | E2: 0 | F2: { } | G2: 1973.16 | H2: SP_INVOICE_ENTRY_STATUS_DISCREPANCY | I2: 111 | K2: Net price discrepancy | M2: SGD | N2: =COUNTIF('HO data'!B:B,'SP Invoice Report'!C2) -> 1
A3: 25569 | C3: 28028088 | E3: 0 | F3: { } | G3: 565 | H3: SP_INVOICE_ENTRY_STATUS_ALREADY_MANUALLY_RECONCILED | I3: 111 | K3: Reconciliation ALREADY manually reconciled | M3: SGD | N3: =COUNTIF('HO data'!B:B,'SP Invoice Report'!C3) -> 1
A4: 25569 | C4: 28045518 | E4: 0 | F4: { } | G4: 320.28 | H4: SP_INVOICE_ENTRY_STATUS_DISCREPANCY | I4: 111 | K4: Net price discrepancy | M4: SGD | N4: =COUNTIF('HO data'!B:B,'SP Invoice Report'!C4) -> 1
A5: 25569 | C5: 28584208 | E5: 0 | F5: { } | G5: -144.27 | H5: SP_INVOICE_ENTRY_STATUS_DISCREPANCY | I5: 111 | K5: No successful reconciliation found against booking id | M5: SGD | N5: =COUNTIF('HO data'!B:B,'SP Invoice Report'!C5) -> 1
A6: 25569 | C6: 28731825 | E6: 0 | F6: { } | G6: -81.72 | H6: SP_INVOICE_ENTRY_STATUS_DISCREPANCY | I6: 111 | K6: No successful reconciliation found against booking id | M6: SGD | N6: =COUNTIF('HO data'!B:B,'SP Invoice Report'!C6) -> 1
A7: 25569 | C7: 28994240 | E7: 0 | F7: { } | G7: -74.4 | H7: SP_INVOICE_ENTRY_STATUS_DISCREPANCY | I7: 111 | K7: No successful reconciliation found against booking id | M7: SGD | N7: =COUNTIF('HO data'!B:B,'SP Invoice Report'!C7) -> 1
A8: 25569 | C8: 29003064 | E8: 0 | F8: { } | G8: 287 | H8: SP_INVOICE_ENTRY_STATUS_DISCREPANCY | I8: 111 | K8: Net price discrepancy | M8: SGD | N8: =COUNTIF('HO data'!B:B,'SP Invoice Report'!C8) -> 1
A9: 25569 | C9: 29036584 | E9: 0 | F9: { } | G9: -57.72 | H9: SP_INVOICE_ENTRY_STATUS_DISCREPANCY | I9: 111 | K9: Net price discrepancy | M9: SGD | N9: =COUNTIF('HO data'!B:B,'SP Invoice Report'!C9) -> 1
A10: 25569 | C10: 29170286 | E10: 0 | F10: { } | G10: -163.08 | H10: SP_INVOICE_ENTRY_STATUS_DISCREPANCY | I10: 111 | K10: Net price discrepancy | M10: SGD | N10: =COUNTIF('HO data'!B:B,'SP Invoice Report'!C10) -> 1
A11: 25569 | C11: 29197289 | E11: 0 | F11: { } | G11: -94.6 | H11: SP_INVOICE_ENTRY_STATUS_DISCREPANCY | I11: 111 | K11: No successful reconciliation found against booking id | M11: SGD | N11: =COUNTIF('HO data'!B:B,'SP Invoice Report'!C11) -> 1
A12: 25569 | C12: 29213576 | E12: 0 | F12: { } | G12: -99.6 | H12: SP_INVOICE_ENTRY_STATUS_DISCREPANCY | I12: 111 | K12: Net price discrepancy | M12: SGD | N12: =COUNTIF('HO data'!B:B,'SP Invoice Report'!C12) -> 1
A13: 25569 | C13: 29238696 | E13: 0 | F13: { } | G13: -166 | H13: SP_INVOICE_ENTRY_STATUS_DISCREPANCY | I13: 111 | K13: No successful reconciliation found against booking id | M13: SGD | N13: =COUNTIF('HO data'!B:B,'SP Invoice Report'!C13) -> 1
... A6749: 25569 | C6749: 29767057 | E6749: 0 | F6749: { } | G6749: 68.95 | H6749: SP_INVOICE_ENTRY_STATUS_UNRESOLVED | I6749: 111 | K6749: No matching reconciliations found | M6749: SGD | N6749: =COUNTIF('HO data'!B:B,'SP Invoice Report'!C6749) -> 0
A6750: 25569 | C6750: (blank) | E6750: 0 | F6750: { } | G6750: 208.63 | H6750: SP_INVOICE_ENTRY_STATUS_UNRESOLVED | I6750: 111 | K6750: No matching reconciliations found | M6750: SGD | N6750: =COUNTIF('HO data'!B:B,'SP Invoice Report'!C6750) -> 0

Sheet HO data
A1: id | B1: bookingId | C1: fulfilmentId | D1: bookingCreationDate | E1: experienceDate | F1: fulfilmentStatus | G1: tgid | H1: tid | I1: experienceName | J1: tourName | K1: billingEntityName | L1: beId | M1: vendorName | N1: vid | O1: fulfilmentMethod | P1: paymentMethod | Q1: primaryGuestName | R1: persons | S1: paymentBasis | T1: spBookingRefNumber | U1: internalPaymentRefNumber | V1: status | W1: actor | X1: version | Y1: createdAt | Z1: updatedAt | AA1: currency | AB1: headoutSellingPrice | AC1: netPrice | AD1: extraCharges | AE1: partiallyFulfilled | AF1: bookingStatus | AG1: finalNetPrice | AH1: finalVendorId | AI1: chargedLoss | AJ1: errorTeamAttribution | AK1: errorBucket | AL1: comments | AM1: reconcileManually | AN1: reason | AO1: adult_count | AP1: adult_unit_price | AQ1: adult_price_net | AR1: adult_non_resident_count | AS1: adult_non_resident_unit_price | AT1: adult_non_resident_price_net | AU1: child_count | AV1: child_unit_price | AW1: child_price_net | AX1: concession_count | AY1: concession_unit_price | AZ1: concession_price_net | BA1: family_2_adult_2_children_count | BB1: family_2_adult_2_children_unit_price | BC1: family_2_adult_2_children_price_net | BD1: general_count | BE1: general_unit_price | BF1: general_price_net | BG1: malaysian_adult_count | BH1: malaysian_adult_unit_price | BI1: malaysian_adult_price_net | BJ1: non_malaysian_adult_count | BK1: non_malaysian_adult_unit_price | BL1: non_malaysian_adult_price_net | BM1: non_malaysian_child_count | BN1: non_malaysian_child_unit_price | BO1: non_malaysian_child_price_net | BP1: non_malaysian_senior_count | BQ1: non_malaysian_senior_unit_price | BR1: non_malaysian_senior_price_net | BS1: senior_count | BT1: senior_unit_price | BU1: senior_price_net | BV1: youth_count | BW1: youth_unit_price | BX1: youth_price_net
A2: reconciliation_2061782626271089 | B2: 27697547 | C2: 15908597 | D2: 46044.933 | E2: 46065 | F2: SUCCESS | G2: 31276 | H2: 65471 | I2: Universal Studios Hollywood - VIP Experience | K2: BeMyGuest | L2: 111 | M2: BeMyGuest_API | N2: 2992 | O2: MANUAL | P2: PORTAL_DEPOSIT | Q2: Mariano Luis Vignolo | R2: { "totalCount": 4, "personList": [{ "count": 4, "type": "GENERAL", "priceNet": 351.0 }] } | S2: DATE_OF_BOOKING | T2: UNHN9DB | U2: TODO | V2: RECONCILIATION_STATUS_MANUALLY_RECONCILED | W2: RECON | X2: 2 | Y2: 46044.933 | Z2: 46073.389 | AA2: USD | AB2: 1560 | AC2: 1508.4 | AD2: { "extraCharges": [{ "amountInTourCurrency": 78.0, "chargeType": "PERCENTAGE", "extraChargeCode": "CONVENIENCE_FEE", "chargeValue": 5.0 }] } | AE2: FALSE | AF2: COMPLETED | AI2: FALSE | AL2: Forex | AM2: FALSE | AN2: Net price discrepancy | BD2: 4 | BE2: 351 | BF2: 1404
A3: reconciliation_1456757280455269 | B3: 28028088 | C3: 15645127 | D3: 46024.357 | E3: 46028 | F3: SUCCESS | G3: 14274 | H3: 27070 | I3: Dolphin Encounter + S.E.A. Aquarium | K3: BeMyGuest | L3: 111 | M3: BeMyGuest_API | N3: 2992 | O3: MANUAL | P3: PORTAL_DEPOSIT | Q3: Simon Cross | R3: { "totalCount": 4, "personList": [{ "count": 2, "type": "ADULT", "priceNet": 127.3 }, { "count": 2, "type": "CHILD", "priceNet": 120.3 }] } | S3: DATE_OF_BOOKING | T3: V5UVERN | U3: TODO | V3: RECONCILIATION_STATUS_MANUALLY_RECONCILED | W3: RECON | X3: 3 | Y3: 46024.357 | Z3: 46073.389 | AA3: SGD | AB3: 578 | AC3: 565 | AD3: { } | AE3: FALSE | AF3: COMPLETED | AI3: FALSE | AJ3: Inventory | AK3: Pricing | AL3: Price Mismatch | AM3: FALSE | AN3: Reconciliation ALREADY manually reconciled | AO3: 2 | AP3: 127.3 | AQ3: 254.6 | AU3: 2 | AV3: 120.3 | AW3: 240.6
A4: reconciliation_2341521479663035 | B4: 28045518 | C4: 15787789 | D4: 46034.597 | E4: 46062 | F4: SUCCESS | G4: 1214 | H4: 61933 | I4: Warner Bros. Studio Tour Hollywood - Guided Tour in Spanish | K4: BeMyGuest | L4: 111 | M4: BeMyGuest_API | N4: 2992 | O4: MANUAL | P4: PORTAL_DEPOSIT | Q4: Mariano Luis Vignolo | R4: { "totalCount": 4, "personList": [{ "count": 4, "type": "GENERAL", "priceNet": 68.24 }] } | S4: DATE_OF_BOOKING | T4: UKJQ7ZP | U4: TODO | V4: RECONCILIATION_STATUS_MANUALLY_RECONCILED | W4: RECON | X4: 3 | Y4: 46034.597 | Z4: 46073.389 | AA4: USD | AB4: 304 | AC4: 250.02 | AD4: { } | AE4: FALSE | AF4: COMPLETED | AI4: FALSE | AJ4: Inventory | AK4: Pricing | AL4: Price Mismatch | AM4: FALSE | AN4: Net price discrepancy | BD4: 4 | BE4: 68.24 | BF4: 272.96
A5: reconciliation_758187959016748 | B5: 28584208 | C5: 15003347 | D5: 45980.976 | E5: 46010 | F5: CANCELLED | G5: 14126 | H5: 26842 | I5: Museum of the Future - Admission | K5: BeMyGuest | L5: 111 | M5: BeMyGuest_API | N5: 2992 | O5: VENDOR_API | P5: PORTAL_DEPOSIT | Q5: EVGENIIA Barashova | R5: { "totalCount": 3, "personList": [{ "count": 3, "type": "ADULT", "priceNet": 135.2 }] } | S5: DATE_OF_BOOKING | T5: 37707a31-72a8-4aed-a234-6f3cde17d72d | U5: TODO | V5: RECONCILIATION_STATUS_MANUALLY_RECONCILED | W5: RECON | X5: 10 | Y5: 45980.976 | Z5: 46073.389 | AA5: AED | AB5: 507 | AC5: 0 | AD5: { } | AE5: TRUE | AF5: CANCELLED | AI5: FALSE | AL5: Refunded | AM5: FALSE | AN5: No successful reconciliation found against booking id | AO5: 3 | AP5: 135.2 | AQ5: 405.6
A6: reconciliation_110204235101463 | B6: 28731825 | C6: 15120801 | D6: 45990.637 | E6: 46047 | F6: CANCELLED | G6: 31468 | H6: 63735 | I6: Central Park Zoo - Admission | K6: BeMyGuest | L6: 111 | M6: BeMyGuest_API | N6: 2992 | O6: VENDOR_API | P6: PORTAL_DEPOSIT | Q6: Elvin soto medina | R6: { "totalCount": 4, "personList": [{ "count": 2, "type": "ADULT", "priceNet": 18.06 }, { "count": 2, "type": "CHILD", "priceNet": 13.45 }] } | S6: DATE_OF_BOOKING | T6: cd014b5c-80b1-49bc-981b-388934017ac9 | U6: TODO | V6: RECONCILIATION_STATUS_MANUALLY_RECONCILED | W6: RECON | X6: 10 | Y6: 45990.637 | Z6: 46073.389 | AA6: USD | AB6: 64.4 | AC6: 0 | AD6: { "extraCharges": [{ "amountInTourCurrency": 12.0, "chargeType": "ABSOLUTE", "extraChargeCode": "CONVENIENCE_FEE", "chargeValue": 3.0 }] } | AE6: TRUE | AF6: CANCELLED | AI6: FALSE | AL6: Refunded | AM6: FALSE | AN6: No successful reconciliation found against booking id | AO6: 2 | AP6: 18.06 | AQ6: 36.12 | AU6: 2 | AV6: 13.45 | AW6: 26.9
A7: reconciliation_14969088203100 | B7: 28994240 | C7: 15332595 | D7: 46006.644 | E7: 46023 | F7: CANCELLED | G7: 7371 | H7: 55603 | I7: Marina Bay Sands SkyPark Observation Deck - Admission (Timeslot Entry from 5:00 PM) | K7: BeMyGuest | L7: 111 | M7: BeMyGuest_API | N7: 2992 | O7: VENDOR_API | P7: PORTAL_DEPOSIT | Q7: Andre Peter Lukoschat | R7: { "totalCount": 2, "personList": [{ "count": 2, "type": "ADULT", "priceNet": 37.2 }] } | S7: DATE_OF_BOOKING | T7: 3216880c-a285-4c55-8b03-89c61a624c19 | U7: TODO | V7: RECONCILIATION_STATUS_MANUALLY_RECONCILED | W7: RECON | X7: 11 | Y7: 46006.644 | Z7: 46073.389 | AA7: SGD | AB7: 78 | AC7: 0 | AD7: { "extraCharges": [{ "amountInTourCurrency": 7.8, "chargeType": "PERCENTAGE", "extraChargeCode": "CONVENIENCE_FEE", "chargeValue": 10.0 }] } | AE7: TRUE | AF7: CANCELLED | AI7: FALSE | AL7: Refunded | AM7: FALSE | AN7: No successful reconciliation found against booking id | AO7: 2 | AP7: 37.2 | AQ7: 74.4
A8: reconciliation_2502688021939251 | B8: 29003064 | C8: 15733734 | D8: 46030.477 | E8: 46032 | F8: SUCCESS | G8: 21554 | H8: 42293 | I8: Lunch at Eiffel Tower's Madame Brasserie - Madame Menu with Drinks | K8: BeMyGuest | L8: 111 | M8: BeMyGuest_API | N8: 2992 | O8: MANUAL | P8: HEADOUT_STANDARD_REPORTING | Q8: SOUCHON SEBASTIEN | R8: { "totalCount": 2, "personList": [{ "count": 2, "type": "ADULT", "priceNet": 91.27 }] } | S8: DATE_OF_BOOKING | T8: SU8X2E4 | U8: TODO | V8: RECONCILIATION_STATUS_MANUALLY_RECONCILED | W8: RECON | X8: 2 | Y8: 46030.477 | Z8: 46073.389 | AA8: EUR | AB8: 200.6 | AC8: 190.92 | AD8: { } | AE8: FALSE | AF8: COMPLETED | AI8: FALSE | AL8: Reconciled | AM8: FALSE | AN8: Net price discrepancy | AO8: 2 | AP8: 91.27 | AQ8: 182.54
A9: reconciliation_662306821688034 | B9: 29036584 | C9: 15364545 | D9: 46009.176 | E9: 46009 | F9: SUCCESS | G9: 11873 | H9: 22709 | I9: SkyPoint Observation Deck - Admission | K9: BeMyGuest | L9: 111 | M9: BeMyGuest_API | N9: 2992 | O9: VENDOR_API | P9: PORTAL_DEPOSIT | Q9: Sandhya Bhandari | R9: { "totalCount": 3, "personList": [{ "count": 3, "type": "ADULT", "priceNet": 22.58 }] } | S9: DATE_OF_BOOKING | T9: 65a6c659-08c5-46bb-b24b-4629760b9a85 | U9: TODO | V9: RECONCILIATION_STATUS_MANUALLY_RECONCILED | W9: RECON | X9: 9 | Y9: 46009.176 | Z9: 46073.389 | AA9: AUD | AB9: 96.78 | AC9: 0 | AD9: { } | AE9: TRUE | AF9: CANCELLED | AI9: FALSE | AL9: Refunded | AM9: FALSE | AN9: Net price discrepancy | AO9: 3 | AP9: 22.58 | AQ9: 67.74
A10: reconciliation_1230771134651821 | B10: 29170286 | C10: 15469696 | D10: 46015.756 | E10: 46024 | F10: SUCCESS | G10: 10055 | H10: 18487 | I10: Dubai Mega Yacht Dinner Cruise (Food and Soft Drinks Package) | K10: BeMyGuest | L10: 111 | M10: BeMyGuest_API | N10: 2992 | O10: VENDOR_API | P10: PORTAL_DEPOSIT | Q10: Awatif Rabbani | R10: { "totalCount": 2, "personList": [{ "count": 2, "type": "ADULT", "priceNet": 233.22 }] } | S10: DATE_OF_BOOKING | T10: 5222196a-6d89-45a9-b793-9a677fca5053 | U10: TODO | V10: RECONCILIATION_STATUS_AUTO_RECONCILED | W10: RECON | X10: 7 | Y10: 46015.756 | Z10: 46073.389 | AA10: AED | AB10: 598 | AC10: 0 | AD10: { } | AE10: TRUE | AF10: COMPLETED | AI10: FALSE | AL10: Refunded | AM10: FALSE | AN10: Net price discrepancy | AO10: 2 | AP10: 233.22 | AQ10: 466.44
A11: reconciliation_1345474853876359 | B11: 29197289 | C11: 15490331 | D11: 46017.083 | E11: 46017 | F11: CANCELLED | G11: 7371 | H11: 13460 | I11: Marina Bay Sands SkyPark Observation Deck - Admission (Entry until 4:00 PM) | K11: BeMyGuest | L11: 111 | M11: BeMyGuest_API | N11: 2992 | O11: VENDOR_API | P11: PORTAL_DEPOSIT | Q11: Marc Latournarie | R11: { "totalCount": 3, "personList": [{ "count": 2, "type": "ADULT", "priceNet": 33.2 }, { "count": 1, "type": "SENIOR", "priceNet": 28.2 }] } | S11: DATE_OF_BOOKING | T11: 844b492b-88ca-437c-b8a6-33c65f56fa2f | U11: TODO | V11: RECONCILIATION_STATUS_MANUALLY_RECONCILED | W11: RECON | X11: 11 | Y11: 46017.083 | Z11: 46073.389 | AA11: SGD | AB11: 101 | AC11: 0 | AD11: { "extraCharges": [{ "amountInTourCurrency": 10.1, "chargeType": "PERCENTAGE", "extraChargeCode": "CONVENIENCE_FEE", "chargeValue": 10.0 }] } | AE11: TRUE | AF11: CANCELLED | AI11: FALSE | AL11: Refunded | AM11: FALSE | AN11: No successful reconciliation found against booking id | AO11: 2 | AP11: 33.2 | AQ11: 66.4 | BS11: 1 | BT11: 28.2 | BU11: 28.2
A12: reconciliation_879136920198032 | B12: 29213576 | C12: 15503579 | D12: 46017.671 | E12: 46019 | F12: SUCCESS | G12: 17237 | H12: 13460 | I12: Marina Bay Sands SkyPark Observation Deck - Admission (Entry until 4:00 PM) | K12: BeMyGuest | L12: 111 | M12: BeMyGuest_API | N12: 2992 | O12: VENDOR_API | P12: PORTAL_DEPOSIT | Q12: Urte Venclovaite | R12: { "totalCount": 3, "personList": [{ "count": 3, "type": "ADULT", "priceNet": 33.2 }] } | S12: DATE_OF_BOOKING | T12: 7eee340d-48b7-4d6f-969a-c3a297f39025 | U12: TODO | V12: RECONCILIATION_STATUS_AUTO_RECONCILED | W12: RECON | X12: 7 | Y12: 46017.671 | Z12: 46073.389 | AA12: SGD | AB12: 91.95 | AC12: 0 | AD12: { "extraCharges": [{ "amountInTourCurrency": 9.194, "chargeType": "PERCENTAGE", "extraChargeCode": "CONVENIENCE_FEE", "chargeValue": 10.0 }] } | AE12: TRUE | AF12: COMPLETED | AI12: FALSE | AL12: Refunded | AM12: FALSE | AN12: Net price discrepancy | AO12: 3 | AP12: 33.2 | AQ12: 99.6
A13: reconciliation_1475726062034150 | B13: 29238696 | C13: 15523212 | D13: 46018.591 | E13: 46019 | F13: CANCELLED | G13: 7371 | H13: 13460 | I13: Marina Bay Sands SkyPark Observation Deck - Admission (Entry until 4:00 PM) | K13: BeMyGuest | L13: 111 | M13: BeMyGuest_API | N13: 2992 | O13: VENDOR_API | P13: PORTAL_DEPOSIT | Q13: FRANCISCO MANUEL GONZALVEZ ALBERO | R13: { "totalCount": 5, "personList": [{ "count": 5, "type": "ADULT", "priceNet": 33.2 }] } | S13: DATE_OF_BOOKING | T13: d048df6d-844b-45e8-9817-2da63d436f04 | U13: TODO | V13: RECONCILIATION_STATUS_MANUALLY_RECONCILED | W13: RECON | X13: 11 | Y13: 46018.591 | Z13: 46073.389 | AA13: SGD | AB13: 175 | AC13: 0 | AD13: { "extraCharges": [{ "amountInTourCurrency": 17.5, "chargeType": "PERCENTAGE", "extraChargeCode": "CONVENIENCE_FEE", "chargeValue": 10.0 }] } | AE13: TRUE | AF13: CANCELLED | AI13: FALSE | AL13: Refunded | AM13: FALSE | AN13: No successful reconciliation found against booking id | AO13: 5 | AP13: 33.2 | AQ13: 166
A14: reconciliation_1476562732919418 | B14: 29239028 | C14: 15523489 | D14: 46018.601 | E14: 46019 | F14: CANCELLED | G14: 17237 | H14: 13460 | I14: Marina Bay Sands SkyPark Observation Deck - Admission (Entry until 4:00 PM) | K14: BeMyGuest | L14: 111 | M14: BeMyGuest_API | N14: 2992 | O14: VENDOR_API | P14: PORTAL_DEPOSIT | Q14: Minseo Kim | R14: { "totalCount": 5, "personList": [{ "count": 5, "type": "ADULT", "priceNet": 33.2 }] } | S14: DATE_OF_BOOKING | T14: d7fe957e-6793-4754-ad73-535953c40a46 | U14: TODO | V14: RECONCILIATION_STATUS_MANUALLY_RECONCILED | W14: RECON | X14: 10 | Y14: 46018.601 | Z14: 46073.389 | AA14: SGD | AB14: 166.25 | AC14: 0 | AD14: { "extraCharges": [{ "amountInTourCurrency": 16.623, "chargeType": "PERCENTAGE", "extraChargeCode": "CONVENIENCE_FEE", "chargeValue": 10.0 }] } | AE14: TRUE | AF14: CANCELLED | AI14: FALSE | AL14: Refunded | AM14: FALSE | AN14: No successful reconciliation found against booking id | AO14: 5 | AP14: 33.2 | AQ14: 166
A15: reconciliation_1100671665552518 | B15: 29283815 | C15: 15559256 | D15: 46020.235 | E15: 46020 | F15: SUCCESS | G15: 17825 | H15: 62106 | I15: TWO-ATTRACTION COMBO: Genting SkyWorlds + Skytropolis Indoor Theme Park (Non-Malaysian) | K15: BeMyGuest | L15: 111 | M15: BeMyGuest_API | N15: 2992 | O15: VENDOR_API | P15: PORTAL_DEPOSIT | Q15: AISHWARYA VINEETH NAIR | R15: { "totalCount": 4, "personList": [{ "count": 4, "type": "NON_MALAYSIAN_ADULT", "priceNet": 178.0 }] } | S15: DATE_OF_BOOKING | T15: 9af3c978-eb7c-48eb-82eb-7b98310681fd | U15: TODO | V15: RECONCILIATION_STATUS_MANUALLY_RECONCILED | W15: RECON | X15: 7 | Y15: 46020.235 | Z15: 46073.389 | AA15: MYR | AB15: 812 | AC15: 0 | AD15: { } | AE15: TRUE | AF15: COMPLETED | AI15: FALSE | AL15: Refunded | AM15: FALSE | AN15: Net price discrepancy | BJ15: 4 | BK15: 178 | BL15: 712
A16: reconciliation_1191614916033869 | B16: 29315188 | C16: 15584507 | D16: 46021.288 | E16: 46022 | F16: FAILED | G16: 17825 | H16: 62106 | I16: TWO-ATTRACTION COMBO: Genting SkyWorlds + Skytropolis Indoor Theme Park (Non-Malaysian) | K16: BeMyGuest | L16: 111 | M16: BeMyGuest_API | N16: 2992 | O16: VENDOR_API | P16: PORTAL_DEPOSIT | Q16: Nengsih Nengsih | R16: { "totalCount": 1, "personList": [{ "count": 1, "type": "NON_MALAYSIAN_ADULT", "priceNet": 178.0 }] } | S16: DATE_OF_BOOKING | U16: TODO | V16: RECONCILIATION_STATUS_DISCREPANCY | W16: RECON | X16: 4 | Y16: 46021.288 | Z16: 46027.414 | AA16: MYR | AB16: 203 | AC16: 178 | AD16: { } | AE16: FALSE | AF16: CANCELLED | AI16: FALSE | AM16: FALSE | AN16: No successful reconciliation found against booking id | BJ16: 1 | BK16: 178 | BL16: 178
A17: reconciliation_1195440048336645 | B17: 29315188 | C17: 15585661 | D17: 46021.332 | E17: 46022 | F17: FAILED | G17: 17825 | H17: 62106 | I17: TWO-ATTRACTION COMBO: Genting SkyWorlds + Skytropolis Indoor Theme Park (Non-Malaysian) | K17: BeMyGuest | L17: 111 | M17: BeMyGuest_API | N17: 2992 | O17: VENDOR_API | P17: PORTAL_DEPOSIT | Q17: Nengsih Nengsih | R17: { "totalCount": 1, "personList": [{ "count": 1, "type": "NON_MALAYSIAN_ADULT", "priceNet": 178.0 }] } | S17: DATE_OF_BOOKING | U17: TODO | V17: RECONCILIATION_STATUS_DISCREPANCY | W17: RECON | X17: 4 | Y17: 46021.332 | Z17: 46027.414 | AA17: MYR | AB17: 203 | AC17: 178 | AD17: { } | AE17: FALSE | AF17: CANCELLED | AI17: FALSE | AM17: FALSE | AN17: No successful reconciliation found against booking id | BJ17: 1 | BK17: 178 | BL17: 178
A18: reconciliation_1208745624076272 | B18: 29315188 | C18: 15591266 | D18: 46021.486 | E18: 46022 | F18: FAILED | G18: 17825 | H18: 62106 | I18: TWO-ATTRACTION COMBO: Genting SkyWorlds + Skytropolis Indoor Theme Park (Non-Malaysian) | K18: BeMyGuest | L18: 111 | M18: BeMyGuest_API | N18: 2992 | O18: VENDOR_API | P18: PORTAL_DEPOSIT | Q18: Nengsih Nengsih | R18: { "totalCount": 1, "personList": [{ "count": 1, "type": "NON_MALAYSIAN_ADULT", "priceNet": 178.0 }] } | S18: DATE_OF_BOOKING | U18: TODO | V18: RECONCILIATION_STATUS_DISCREPANCY | W18: RECON | X18: 4 | Y18: 46021.486 | Z18: 46027.414 | AA18: MYR | AB18: 203 | AC18: 178 | AD18: { } | AE18: FALSE | AF18: CANCELLED | AI18: FALSE | AM18: FALSE | AN18: No successful reconciliation found against booking id | BJ18: 1 | BK18: 178 | BL18: 178
A19: reconciliation_1214769412849889 | B19: 29315188 | C19: 15593717 | D19: 46021.556 | E19: 46022 | F19: FAILED | G19: 17825 | H19: 62106 | I19: TWO-ATTRACTION COMBO: Genting SkyWorlds + Skytropolis Indoor Theme Park (Non-Malaysian) | K19: BeMyGuest | L19: 111 | M19: BeMyGuest_API | N19: 2992 | O19: VENDOR_API | P19: PORTAL_DEPOSIT | Q19: Nengsih Nengsih | R19: { "totalCount": 1, "personList": [{ "count": 1, "type": "NON_MALAYSIAN_ADULT", "priceNet": 178.0 }] } | S19: DATE_OF_BOOKING | U19: TODO | V19: RECONCILIATION_STATUS_DISCREPANCY | W19: RECON | X19: 4 | Y19: 46021.556 | Z19: 46027.414 | AA19: MYR | AB19: 203 | AC19: 178 | AD19: { } | AE19: FALSE | AF19: CANCELLED | AI19: FALSE | AM19: FALSE | AN19: No successful reconciliation found against booking id | BJ19: 1 | BK19: 178 | BL19: 178
A20: reconciliation_1712352006973451 | B20: 29315188 | C20: 15585582 | D20: 46021.33 | E20: 46022 | F20: FAILED | G20: 17825 | H20: 62106 | I20: TWO-ATTRACTION COMBO: Genting SkyWorlds + Skytropolis Indoor Theme Park (Non-Malaysian) | K20: BeMyGuest | L20: 111 | M20: BeMyGuest_API | N20: 2992 | O20: VENDOR_API | P20: PORTAL_DEPOSIT | Q20: Nengsih Nengsih | R20: { "totalCount": 1, "personList": [{ "count": 1, "type": "NON_MALAYSIAN_ADULT", "priceNet": 178.0 }] } | S20: DATE_OF_BOOKING | U20: TODO | V20: RECONCILIATION_STATUS_DISCREPANCY | W20: RECON | X20: 4 | Y20: 46021.33 | Z20: 46027.414 | AA20: MYR | AB20: 203 | AC20: 178 | AD20: { } | AE20: FALSE | AF20: CANCELLED | AI20: FALSE | AM20: FALSE | AN20: No successful reconciliation found against booking id | BJ20: 1 | BK20: 178 | BL20: 178
A21: reconciliation_1779130856406389 | B21: 29339921 | C21: 15604222 | D21: 46022.102 | E21: 46029 | F21: SUCCESS | G21: 24204 | H21: 26872 | I21: SEA LIFE Sydney Aquarium - Morning Admission | K21: BeMyGuest | L21: 111 | M21: BeMyGuest_Peak | N21: 2145 | O21: VENDOR_API | P21: PORTAL_DEPOSIT | Q21: Nigela Bagtang | R21: { "totalCount": 2, "personList": [{ "count": 1, "type": "ADULT", "priceNet": 32.53 }, { "count": 1, "type": "CHILD", "priceNet": 23.5 }] } | S21: DATE_OF_BOOKING | T21: bf3b5613-d61a-4d23-9f6c-2ebe026ebcda | U21: TODO | V21: RECONCILIATION_STATUS_MANUALLY_RECONCILED | W21: RECON | X21: 10 | Y21: 46022.102 | Z21: 46073.389 | AA21: AUD | AB21: 82.12 | AC21: 0 | AD21: { } | AE21: TRUE | AF21: CANCELLED | AI21: FALSE | AL21: Refunded | AM21: FALSE | AN21: Net price discrepancy | AO21: 1 | AP21: 32.53 | AQ21: 32.53 | AU21: 1 | AV21: 23.5 | AW21: 23.5
A22: reconciliation_1310270924605903 | B22: 29354020 | C22: 15615587 | D22: 46022.661 | E22: 46022 | F22: FAILED | G22: 11655 | H22: 22128 | I22: General Admission | K22: BeMyGuest | L22: 111 | M22: BeMyGuest_API | N22: 2992 | O22: VENDOR_API | P22: PORTAL_DEPOSIT | Q22: Claire Guilmette | R22: { "totalCount": 2, "personList": [{ "count": 2, "type": "ADULT", "priceNet": 31.19 }] } | S22: DATE_OF_BOOKING | U22: TODO | V22: RECONCILIATION_STATUS_PENDING | W22: RECON | X22: 3 | Y22: 46022.661 | Z22: 46022.683 | AA22: USD | AB22: 78 | AC22: 62.38 | AD22: { "extraCharges": [{ "amountInTourCurrency": 4.0, "chargeType": "ABSOLUTE", "extraChargeCode": "CONVENIENCE_FEE", "chargeValue": 2.0 }] } | AE22: FALSE | AF22: COMPLETED | AI22: FALSE | AM22: FALSE | AN22: Net price discrepancy | AO22: 2 | AP22: 31.19 | AQ22: 62.38
A23: reconciliation_1828658328199959 | B23: 29354020 | C23: 15615858 | D23: 46022.676 | E23: 46022 | F23: SUCCESS | G23: 11655 | H23: 22128 | I23: General Admission | K23: BeMyGuest | L23: 111 | M23: BeMyGuest_API | N23: 2992 | O23: VENDOR_API | P23: PORTAL_DEPOSIT | Q23: Claire Guilmette | R23: { "totalCount": 2, "personList": [{ "count": 2, "type": "ADULT", "priceNet": 31.19 }] } | S23: DATE_OF_BOOKING | T23: 69a699bd-29cd-4397-ad51-0c36b6efe2a5 | U23: TODO | V23: RECONCILIATION_STATUS_AUTO_RECONCILED | W23: RECON | X23: 7 | Y23: 46022.676 | Z23: 46073.389 | AA23: USD | AB23: 78 | AC23: 62.62 | AD23: { "extraCharges": [{ "amountInTourCurrency": 4.0, "chargeType": "ABSOLUTE", "extraChargeCode": "CONVENIENCE_FEE", "chargeValue": 2.0 }] } | AE23: TRUE | AF23: COMPLETED | AI23: FALSE | AL23: Reconciled | AM23: FALSE | AN23: Net price discrepancy | AO23: 2 | AP23: 31.19 | AQ23: 62.38
A24: reconciliation_1311120122806390 | B24: 29354284 | C24: 15615785 | D24: 46022.671 | E24: 46022 | F24: SUCCESS | G24: 31468 | H24: 63735 | I24: Central Park Zoo - Admission | K24: BeMyGuest | L24: 111 | M24: BeMyGuest_API | N24: 2992 | O24: VENDOR_API | P24: PORTAL_DEPOSIT | Q24: Viviana Palomino | R24: { "totalCount": 2, "personList": [{ "count": 1, "type": "ADULT", "priceNet": 18.06 }, { "count": 1, "type": "CHILD", "priceNet": 13.45 }] } | S24: DATE_OF_BOOKING | T24: ef6bc8d8-1f04-438f-b406-342b88aba616 | U24: TODO | V24: RECONCILIATION_STATUS_AUTO_RECONCILED | W24: RECON | X24: 7 | Y24: 46022.671 | Z24: 46073.389 | AA24: USD | AB24: 32.2 | AC24: 31.62 | AD24: { "extraCharges": [{ "amountInTourCurrency": 6.0, "chargeType": "ABSOLUTE", "extraChargeCode": "CONVENIENCE_FEE", "chargeValue": 3.0 }] } | AE24: TRUE | AF24: COMPLETED | AI24: FALSE | AL24: Reconciled | AM24: FALSE | AN24: Net price discrepancy | AO24: 1 | AP24: 18.06 | AQ24: 18.06 | AU24: 1 | AV24: 13.45 | AW24: 13.45
A25: reconciliation_1828556142791244 | B25: 29354343 | C25: 15615845 | D25: 46022.675 | E25: 46022 | F25: SUCCESS | G25: 30480 | H25: 63735 | I25: Central Park Zoo - Admission | K25: BeMyGuest | L25: 111 | M25: BeMyGuest_API | N25: 2992 | O25: VENDOR_API | P25: PORTAL_DEPOSIT | Q25: stacey mottram | R25: { "totalCount": 2, "personList": [{ "count": 2, "type": "ADULT", "priceNet": 18.06 }] } | S25: DATE_OF_BOOKING | T25: c81df581-fb15-4ff8-b7b5-7f4daa54f8a4 | U25: TODO | V25: RECONCILIATION_STATUS_AUTO_RECONCILED | W25: RECON | X25: 7 | Y25: 46022.675 | Z25: 46073.389 | AA25: USD | AB25: 39.9 | AC25: 36.25 | AD25: { "extraCharges": [{ "amountInTourCurrency": 6.0, "chargeType": "ABSOLUTE", "extraChargeCode": "CONVENIENCE_FEE", "chargeValue": 3.0 }] } | AE25: TRUE | AF25: COMPLETED | AI25: FALSE | AL25: Reconciled | AM25: FALSE | AN25: Net price discrepancy | AO25: 2 | AP25: 18.06 | AQ25: 36.12
A26: reconciliation_1828752017017451 | B26: 29354391 | C26: 15615875 | D26: 46022.677 | E26: 46023 | F26: SUCCESS | G26: 13224 | H26: 61763 | I26: The Habitat Penang Hill - Standard Entrance Pass | K26: BeMyGuest | L26: 111 | M26: BeMyGuest_API | N26: 2992 | O26: VENDOR_API | P26: PORTAL_DEPOSIT | Q26: Li Cui | R26: { "totalCount": 4, "personList": [{ "count": 3, "type": "ADULT", "priceNet": 43.0 }, { "count": 1, "type": "CHILD", "priceNet": 29.0 }] } | S26: DATE_OF_BOOKING | T26: d4be0068-502f-4609-9030-88f8ad4c8d31 | U26: TODO | V26: RECONCILIATION_STATUS_AUTO_RECONCILED | W26: RECON | X26: 7 | Y26: 46022.677 | Z26: 46073.389 | AA26: MYR | AB26: 187 | AC26: 157.51 | AD26: { } | AE26: TRUE | AF26: COMPLETED | AI26: FALSE | AL26: Reconciled | AM26: FALSE | AN26: Net price discrepancy | AO26: 3 | AP26: 43 | AQ26: 129 | AU26: 1 | AV26: 29 | AW26: 29
A27: reconciliation_1828866281877586 | B27: 29354428 | C27: 15615908 | D27: 46022.678 | E27: 46023 | F27: SUCCESS | G27: 17859 | H27: 52474 | I27: Dtac Happy Tourist 5G SIM Card - THB 349 Plan (Suvarnabumi Airport Pick-up) | K27: BeMyGuest | L27: 111 | M27: BeMyGuest_API | N27: 2992 | O27: VENDOR_API | P27: PORTAL_DEPOSIT | Q27: Sanjana Murali | R27: { "totalCount": 2, "personList": [{ "count": 2, "type": "ADULT", "priceNet": 202.0 }] } | S27: DATE_OF_BOOKING | T27: 372e012f-d2bf-469d-ae39-dbe2accc92dd | U27: TODO | V27: RECONCILIATION_STATUS_AUTO_RECONCILED | W27: RECON | X27: 7 | Y27: 46022.678 | Z27: 46073.389 | AA27: THB | AB27: 558 | AC27: 401.06 | AD27: { } | AE27: TRUE | AF27: COMPLETED | AI27: FALSE | AL27: Reconciled | AM27: FALSE | AN27: Net price discrepancy | AO27: 2 | AP27: 202 | AQ27: 404
A28: reconciliation_1828930377427998 | B28: 29354460 | C28: 15615928 | D28: 46022.679 | E28: 46022 | F28: SUCCESS | G28: 30480 | H28: 63735 | I28: Central Park Zoo - Admission | K28: BeMyGuest | L28: 111 | M28: BeMyGuest_API | N28: 2992 | O28: VENDOR_API | P28: PORTAL_DEPOSIT | Q28: Miroslav Stoch | R28: { "totalCount": 2, "personList": [{ "count": 1, "type": "ADULT", "priceNet": 18.06 }, { "count": 1, "type": "CHILD", "priceNet": 13.45 }] } | S28: DATE_OF_BOOKING | T28: de05235c-d23d-4c04-849e-cf9d5de17c75 | U28: TODO | V28: RECONCILIATION_STATUS_AUTO_RECONCILED | W28: RECON | X28: 7 | Y28: 46022.679 | Z28: 46073.389 | AA28: USD | AB28: 33.9 | AC28: 31.64 | AD28: { "extraCharges": [{ "amountInTourCurrency": 6.0, "chargeType": "ABSOLUTE", "extraChargeCode": "CONVENIENCE_FEE", "chargeValue": 3.0 }] } | AE28: TRUE | AF28: COMPLETED | AI28: FALSE | AL28: Reconciled | AM28: FALSE | AN28: Net price discrepancy | AO28: 1 | AP28: 18.06 | AQ28: 18.06 | AU28: 1 | AV28: 13.45 | AW28: 13.45
A29: reconciliation_1829166348975412 | B29: 29354523 | C29: 15615990 | D29: 46022.682 | E29: 46030 | F29: SUCCESS | G29: 7442 | H29: 43120 | I29: Universal Studios Singapore - One Day Ticket | K29: BeMyGuest | L29: 111 | M29: BeMyGuest_API | N29: 2992 | O29: VENDOR_API | P29: PORTAL_DEPOSIT | Q29: Shehani Dawundage | R29: { "totalCount": 1, "personList": [{ "count": 1, "type": "ADULT", "priceNet": 75.0 }] } | S29: DATE_OF_BOOKING | T29: 76730203-a652-4ffa-a2de-b44a21abe9a4 | U29: TODO | V29: RECONCILIATION_STATUS_AUTO_RECONCILED | W29: RECON | X29: 7 | Y29: 46022.682 | Z29: 46073.389 | AA29: SGD | AB29: 82.79 | AC29: 75 | AD29: { } | AE29: TRUE | AF29: COMPLETED | AI29: FALSE | AL29: Reconciled | AM29: FALSE | AN29: Reconciliation ALREADY auto reconciled | AO29: 1 | AP29: 75 | AQ29: 75
A30: reconciliation_1312170733490860 | B30: 29354594 | C30: 15616033 | D30: 46022.683 | E30: 46022 | F30: SUCCESS | G30: 30480 | H30: 63735 | I30: Central Park Zoo - Admission | K30: BeMyGuest | L30: 111 | M30: BeMyGuest_API | N30: 2992 | O30: VENDOR_API | P30: PORTAL_DEPOSIT | Q30: Katie arrington | R30: { "totalCount": 2, "personList": [{ "count": 2, "type": "ADULT", "priceNet": 18.06 }] } | S30: DATE_OF_BOOKING | T30: 6d591b9b-d047-4100-8b70-b4d74fc9ae58 | U30: TODO | V30: RECONCILIATION_STATUS_AUTO_RECONCILED | W30: RECON | X30: 7 | Y30: 46022.683 | Z30: 46073.389 | AA30: USD | AB30: 39.9 | AC30: 36.27 | AD30: { "extraCharges": [{ "amountInTourCurrency": 6.0, "chargeType": "ABSOLUTE", "extraChargeCode": "CONVENIENCE_FEE", "chargeValue": 3.0 }] } | AE30: TRUE | AF30: COMPLETED | AI30: FALSE | AL30: Reconciled | AM30: FALSE | AN30: Net price discrepancy | AO30: 2 | AP30: 18.06 | AQ30: 36.12
A31: reconciliation_2481328327825757 | B31: 29354885 | C31: 15730470 | D31: 46030.23 | E31: 46051 | F31: SUCCESS | G31: 7371 | H31: 55603 | I31: Marina Bay Sands SkyPark Observation Deck - Admission (Timeslot Entry from 5:00 PM) | K31: BeMyGuest | L31: 111 | M31: BeMyGuest_API | N31: 2992 | O31: MANUAL | P31: PORTAL_DEPOSIT | Q31: Jakub Kaczmarek | R31: { "totalCount": 6, "personList": [{ "count": 5, "type": "ADULT", "priceNet": 37.2 }, { "count": 1, "type": "CONCESSION", "priceNet": 32.2 }] } | S31: DATE_OF_BOOKING | T31: R6BX95Z | U31: TODO | V31: RECONCILIATION_STATUS_AUTO_RECONCILED | W31: RECON | X31: 3 | Y31: 46030.23 | Z31: 46073.389 | AA31: SGD | AB31: 230 | AC31: 218.2 | AD31: { "extraCharges": [{ "amountInTourCurrency": 23.0, "chargeType": "PERCENTAGE", "extraChargeCode": "CONVENIENCE_FEE", "chargeValue": 10.0 }] } | AE31: FALSE | AF31: COMPLETED | AI31: FALSE | AL31: Reconciled | AM31: FALSE | AN31: Reconciliation ALREADY auto reconciled | AO31: 5 | AP31: 37.2 | AQ31: 186 | AX31: 1 | AY31: 32.2 | AZ31: 32.2
A32: reconciliation_1313678225973341 | B32: 29355022 | C32: 15616358 | D32: 46022.701 | E32: 46022 | F32: SUCCESS | G32: 11655 | H32: 22128 | I32: General Admission | K32: BeMyGuest | L32: 111 | M32: BeMyGuest_API | N32: 2992 | O32: VENDOR_API | P32: PORTAL_DEPOSIT | Q32: Rebecca King | R32: { "totalCount": 3, "personList": [{ "count": 3, "type": "ADULT", "priceNet": 31.19 }] } | S32: DATE_OF_BOOKING | T32: 63f84127-fea2-4be4-80a7-bc1dbc94784b | U32: TODO | V32: RECONCILIATION_STATUS_AUTO_RECONCILED | W32: RECON | X32: 7 | Y32: 46022.701 | Z32: 46073.389 | AA32: USD | AB32: 117 | AC32: 93.98 | AD32: { "extraCharges": [{ "amountInTourCurrency": 6.0, "chargeType": "ABSOLUTE", "extraChargeCode": "CONVENIENCE_FEE", "chargeValue": 2.0 }] } | AE32: TRUE | AF32: COMPLETED | AI32: FALSE | AL32: Reconciled | AM32: FALSE | AN32: Net price discrepancy | AO32: 3 | AP32: 31.19 | AQ32: 93.57
A33: reconciliation_1831236476391228 | B33: 29355133 | C33: 15616450 | D33: 46022.706 | E33: 46022 | F33: SUCCESS | G33: 11655 | H33: 22128 | I33: General Admission | K33: BeMyGuest | L33: 111 | M33: BeMyGuest_API | N33: 2992 | O33: VENDOR_API | P33: PORTAL_DEPOSIT | Q33: Paul Metcalf | R33: { "totalCount": 4, "personList": [{ "count": 2, "type": "ADULT", "priceNet": 31.19 }, { "count": 2, "type": "CHILD", "priceNet": 20.79 }] } | S33: DATE_OF_BOOKING | T33: 7ef1a0d2-58dc-4a11-af4e-12e8e9c37ac4 | U33: TODO | V33: RECONCILIATION_STATUS_AUTO_RECONCILED | W33: RECON | X33: 7 | Y33: 46022.706 | Z33: 46073.389 | AA33: USD | AB33: 129.98 | AC33: 104.42 | AD33: { "extraCharges": [{ "amountInTourCurrency": 8.0, "chargeType": "ABSOLUTE", "extraChargeCode": "CONVENIENCE_FEE", "chargeValue": 2.0 }] } | AE33: TRUE | AF33: COMPLETED | AI33: FALSE | AL33: Reconciled | AM33: FALSE | AN33: Net price discrepancy | AO33: 2 | AP33: 31.19 | AQ33: 62.38 | AU33: 2 | AV33: 20.79 | AW33: 41.58
A34: reconciliation_1314181229560551 | B34: 29355136 | C34: 15616471 | D34: 46022.707 | E34: 46022 | F34: SUCCESS | G34: 30480 | H34: 63735 | I34: Central Park Zoo - Admission | K34: BeMyGuest | L34: 111 | M34: BeMyGuest_API | N34: 2992 | O34: VENDOR_API | P34: PORTAL_DEPOSIT | Q34: Andres Calderon zumbado | R34: { "totalCount": 2, "personList": [{ "count": 2, "type": "ADULT", "priceNet": 18.06 }] } | S34: DATE_OF_BOOKING | T34: 959092e2-0060-4c7e-a59b-8789c98b8888 | U34: TODO | V34: RECONCILIATION_STATUS_AUTO_RECONCILED | W34: RECON | X34: 7 | Y34: 46022.707 | Z34: 46073.389 | AA34: USD | AB34: 39.9 | AC34: 36.27 | AD34: { "extraCharges": [{ "amountInTourCurrency": 6.0, "chargeType": "ABSOLUTE", "extraChargeCode": "CONVENIENCE_FEE", "chargeValue": 3.0 }] } | AE34: TRUE | AF34: COMPLETED | AI34: FALSE | AL34: Reconciled | AM34: FALSE | AN34: Net price discrepancy | AO34: 2 | AP34: 18.06 | AQ34: 36.12
A35: reconciliation_1831695392391970 | B35: 29355265 | C35: 15616558 | D35: 46022.711 | E35: 46069 | F35: SUCCESS | G35: 37400 | H35: 27355 | I35: Universal Studios Singapore One-Time Express Pass (Individual) | K35: BeMyGuest | L35: 111 | M35: BeMyGuest_API | N35: 2992 | O35: VENDOR_API | P35: PORTAL_DEPOSIT | Q35: Malcolm James Workman | R35: { "totalCount": 3, "personList": [{ "count": 3, "type": "ADULT", "priceNet": 124.5 }] } | S35: DATE_OF_BOOKING | T35: 1.6888957e+15 | U35: TODO | V35: RECONCILIATION_STATUS_MANUALLY_RECONCILED | W35: RECON | X35: 5 | Y35: 46022.711 | Z35: 46073.389 | AA35: SGD | AB35: 705 | AC35: 225 | AD35: { } | AE35: FALSE | AF35: COMPLETED | AI35: FALSE | AL35: Combo on BMG | AM35: FALSE | AN35: Reconciliation ALREADY manually reconciled | AO35: 3 | AP35: 124.5 | AQ35: 373.5
A36: reconciliation_1315289446546391 | B36: 29355435 | C36: 15616705 | D36: 46022.719 | E36: 46026 | F36: SUCCESS | G36: 7442 | H36: 43120 | I36: Universal Studios Singapore - One Day Ticket | K36: BeMyGuest | L36: 111 | M36: BeMyGuest_API | N36: 2992 | O36: VENDOR_API | P36: PORTAL_DEPOSIT | Q36: rajesh bodasing | R36: { "totalCount": 5, "personList": [{ "count": 5, "type": "ADULT", "priceNet": 75.0 }] } | S36: DATE_OF_BOOKING | T36: f62f8414-3086-4485-9f63-b74452d4d9fe | U36: TODO | V36: RECONCILIATION_STATUS_AUTO_RECONCILED | W36: RECON | X36: 7 | Y36: 46022.719 | Z36: 46073.389 | AA36: SGD | AB36: 413.95 | AC36: 375 | AD36: { } | AE36: TRUE | AF36: COMPLETED | AI36: FALSE | AL36: Reconciled | AM36: FALSE | AN36: Reconciliation ALREADY auto reconciled | AO36: 5 | AP36: 75 | AQ36: 375
A37: reconciliation_1315451269596834 | B37: 29355529 | C37: 15616734 | D37: 46022.721 | E37: 46022 | F37: SUCCESS | G37: 30480 | H37: 63735 | I37: Central Park Zoo - Admission | K37: BeMyGuest | L37: 111 | M37: BeMyGuest_API | N37: 2992 | O37: VENDOR_API | P37: PORTAL_DEPOSIT | Q37: Israel Quiroz Plata | R37: { "totalCount": 3, "personList": [{ "count": 2, "type": "ADULT", "priceNet": 18.06 }, { "count": 1, "type": "CHILD", "priceNet": 13.45 }] } | S37: DATE_OF_BOOKING | T37: aee8c71b-7bc3-4da4-91ad-be2a6fb3a228 | U37: TODO | V37: RECONCILIATION_STATUS_AUTO_RECONCILED | W37: RECON | X37: 7 | Y37: 46022.721 | Z37: 46073.389 | AA37: USD | AB37: 53.85 | AC37: 49.77 | AD37: { "extraCharges": [{ "amountInTourCurrency": 9.0, "chargeType": "ABSOLUTE", "extraChargeCode": "CONVENIENCE_FEE", "chargeValue": 3.0 }] } | AE37: TRUE | AF37: COMPLETED | AI37: FALSE | AL37: Reconciled | AM37: FALSE | AN37: Net price discrepancy | AO37: 2 | AP37: 18.06 | AQ37: 36.12 | AU37: 1 | AV37: 13.45 | AW37: 13.45
A38: reconciliation_1832762525174658 | B38: 29355565 | C38: 15616772 | D38: 46022.723 | E38: 46022 | F38: SUCCESS | G38: 30480 | H38: 63735 | I38: Central Park Zoo - Admission | K38: BeMyGuest | L38: 111 | M38: BeMyGuest_API | N38: 2992 | O38: VENDOR_API | P38: PORTAL_DEPOSIT | Q38: Danny Fallas | R38: { "totalCount": 1, "personList": [{ "count": 1, "type": "ADULT", "priceNet": 18.06 }] } | S38: DATE_OF_BOOKING | T38: a8fff366-4eeb-4826-b261-42b2c3a3a773 | U38: TODO | V38: RECONCILIATION_STATUS_AUTO_RECONCILED | W38: RECON | X38: 7 | Y38: 46022.723 | Z38: 46073.389 | AA38: USD | AB38: 19.95 | AC38: 18.13 | AD38: { "extraCharges": [{ "amountInTourCurrency": 3.0, "chargeType": "ABSOLUTE", "extraChargeCode": "CONVENIENCE_FEE", "chargeValue": 3.0 }] } | AE38: TRUE | AF38: COMPLETED | AI38: FALSE | AL38: Reconciled | AM38: FALSE | AN38: Net price discrepancy | AO38: 1 | AP38: 18.06 | AQ38: 18.06
A39: reconciliation_1316373130292941 | B39: 29355765 | C39: 15616908 | D39: 46022.732 | E39: 46026 | F39: SUCCESS | G39: 7442 | H39: 43120 | I39: Universal Studios Singapore - One Day Ticket | K39: BeMyGuest | L39: 111 | M39: BeMyGuest_API | N39: 2992 | O39: VENDOR_API | P39: PORTAL_DEPOSIT | Q39: ISHARA BODASING | R39: { "totalCount": 2, "personList": [{ "count": 2, "type": "ADULT", "priceNet": 75.0 }] } | S39: DATE_OF_BOOKING | T39: 16abad2d-43a6-4433-bc39-e3af84284884 | U39: TODO | V39: RECONCILIATION_STATUS_AUTO_RECONCILED | W39: RECON | X39: 7 | Y39: 46022.732 | Z39: 46073.389 | AA39: SGD | AB39: 165.58 | AC39: 150 | AD39: { } | AE39: TRUE | AF39: COMPLETED | AI39: FALSE | AL39: Reconciled | AM39: FALSE | AN39: Reconciliation ALREADY auto reconciled | AO39: 2 | AP39: 75 | AQ39: 150
A40: reconciliation_1834436381610597 | B40: 29356009 | C40: 15617098 | D40: 46022.743 | E40: 46022 | F40: SUCCESS | G40: 11655 | H40: 22128 | I40: General Admission | K40: BeMyGuest | L40: 111 | M40: BeMyGuest_API | N40: 2992 | O40: VENDOR_API | P40: PORTAL_DEPOSIT | Q40: Carlos Maytorena | R40: { "totalCount": 2, "personList": [{ "count": 2, "type": "ADULT", "priceNet": 31.19 }] } | S40: DATE_OF_BOOKING | T40: 1d7692e5-33f9-4490-98dd-5602adee5130 | U40: TODO | V40: RECONCILIATION_STATUS_AUTO_RECONCILED | W40: RECON | X40: 7 | Y40: 46022.743 | Z40: 46073.389 | AA40: USD | AB40: 78 | AC40: 62.64 | AD40: { "extraCharges": [{ "amountInTourCurrency": 4.0, "chargeType": "ABSOLUTE", "extraChargeCode": "CONVENIENCE_FEE", "chargeValue": 2.0 }] } | AE40: TRUE | AF40: COMPLETED | AI40: FALSE | AL40: Reconciled | AM40: FALSE | AN40: Net price discrepancy | AO40: 2 | AP40: 31.19 | AQ40: 62.38
...
